Workbook

Sheet PC SETTING
A1: PC | B1: NO | C1: NOPOL | D1: TERMINAL | E1: PC
A2: 1 | B2: 1 | C2: AD 9780 AB | D2: TLPG LOMBOK | E2: 1
B3: 2 | C3: AE 8018 UG | D3: TLPG TJ PERAK | E3: 1
B4: 3 | C4: AE 8099 UT | D4: TLPG TJ PERAK | E4: 1
B5: 4 | C5: AE 8175 UC | D5: TLPG TJ PERAK | E5: 1
B6: 5 | C6: AE 8458 UF | D6: TLPG TJ PERAK | E6: 1
B7: 6 | C7: AE 8459 UF | D7: TLPG TJ PERAK | E7: 1
B8: 7 | C8: AE 8518 UJ | D8: TLPG TJ PERAK | E8: 1
B9: 8 | C9: AE 8546 UJ | D9: TLPG TJ PERAK | E9: 1
B10: 9 | C10: AE 8639 UP | D10: TLPG TJ PERAK | E10: 1
B11: 10 | C11: AE 8641 UP | D11: TLPG TJ PERAK | E11: 1
B12: 11 | C12: AE 8642 UP | D12: TLPG TJ PERAK | E12: 1
B13: 12 | C13: AE 9061 UJ | D13: TLPG TJ PERAK | E13: 1
B14: 13 | C14: AE 8835 UQ | D14: TLPG TJ PERAK | E14: 1
... B29: 28 | C29: S 8316 AI | D29: TLPG TJ PERAK | E29: 1
A30: 2 | B30: 1 | C30: AD 9838 AB | D30: TLPG LOMBOK | E30: 2
B31: 2 | C31: AD 9877 AB | D31: TLPG LOMBOK | E31: 2
B32: 3 | C32: AE 8845 UT | D32: TLPG TJ PERAK | E32: 2
B33: 4 | C33: AE 8846 UT | D33: TLPG TJ PERAK | E33: 2
B34: 5 | C34: AE 8857 UT | D34: TLPG TJ PERAK | E34: 2
B35: 6 | C35: AE 9401 UJ | D35: TLPG TJ PERAK | E35: 2
B36: 7 | C36: AE 8828 UQ | D36: TLPG TJ PERAK | E36: 2
B37: 8 | C37: AE 9634 UJ | D37: TLPG TJ PERAK | E37: 2
B38: 9 | C38: AG 8016 UC | D38: TLPG TJ PERAK | E38: 2
B39: 10 | C39: AG 8032 YQ | D39: TLPG TJ PERAK | E39: 2
B40: 11 | C40: AG 8070 UW | D40: TLPG TJ PERAK | E40: 2
B41: 12 | C41: AG 9312 UW | D41: TLPG TJ PERAK | E41: 2
B42: 13 | C42: B 9098 SEI | D42: TLPG MEM GRESIK | E42: 2
... B57: 28 | C57: P 8172 UF | D57: TLPG TJ WANGI | E57: 2
A58: 3 | B58: 1 | C58: AG 8079 UZ | D58: TLPG TJ PERAK | E58: 3
B59: 2 | C59: AG 8086 UF | D59: TLPG TJ PERAK | E59: 3
B60: 3 | C60: AG 8087 UF | D60: TLPG TJ PERAK | E60: 3
B61: 4 | C61: AG 8088 UF | D61: TLPG TJ PERAK | E61: 3
B62: 5 | C62: AG 8106 UC | D62: TLPG TJ PERAK | E62: 3
B63: 6 | C63: AG 8126 UF | D63: TLPG TJ PERAK | E63: 3
B64: 7 | C64: AG 8128 UF | D64: TLPG TJ PERAK | E64: 3
B65: 8 | C65: AG 8129 UF | D65: TLPG TJ PERAK | E65: 3
B66: 9 | C66: AG 8152 UL | D66: TLPG TJ PERAK | E66: 3
B67: 10 | C67: AG 8225 UG | D67: TLPG TJ PERAK | E67: 3
B68: 11 | C68: AG 8263 UW | D68: TLPG TJ PERAK | E68: 3
...

Sheet SETTING ROTASI
A1: =IFERROR(__xludf.DUMMYFUNCTION("{""DATA BARU"",""TERMINAL"",""PC AWAL"";FILTER({'PC SETTING'!C2:C23550,'PC SETTING'!D2:D23550,'PC SETTING'!E2:E23550},'PC SETTING'!C2:C23550<>"""")}"),"DATA BARU") -> DATA BARU | B1: =IFERROR(__xludf.DUMMYFUNCTION("""COMPUTED_VALUE"""),"TERMINAL") -> TERMINAL | C1: =IFERROR(__xludf.DUMMYFUNCTION("""COMPUTED_VALUE"""),"PC AWAL") -> PC AWAL | D1: PC AKHIR | E1: PERUSAHAAN | G1: NO | H1: NOPOL | I1: TERMINAL | J1: PC | L1: =IFERROR(__xludf.DUMMYFUNCTION("{""NO"",""DATA BARU"",""TERMINAL"",""PC"";{SEQUENCE(COUNTIF($D$2:$D23550,1)),FILTER($A$2:$A23550,$D$2:$D23550=1),FILTER($B$2:$B23550,$D$2:$D23550=1),FILTER($D$2:$D23550,$D$2:$D23550=1)}}"),"NO") -> NO | M1: =IFERROR(__xludf.DUMMYFUNCTION("""COMPUTED_VALUE"""),"DATA BARU") -> DATA BARU | N1: =IFERROR(__xludf.DUMMYFUNCTION("""COMPUTED_VALUE"""),"TERMINAL") -> TERMINAL | O1: =IFERROR(__xludf.DUMMYFUNCTION("""COMPUTED_VALUE"""),"PC") -> PC | P1: KETERANGAN | R1: =IFERROR(__xludf.DUMMYFUNCTION("{""NO"",""DATA BARU"",""TERMINAL"",""PC"";{SEQUENCE(COUNTIF($D$2:$D23550,2)),FILTER($A$2:$A23550,$D$2:$D23550=2),FILTER($B$2:$B23550,$D$2:$D23550=2),FILTER($D$2:$D23550,$D$2:$D23550=2)}}"),"NO") -> NO | S1: =IFERROR(__xludf.DUMMYFUNCTION("""COMPUTED_VALUE"""),"DATA BARU") -> DATA BARU | T1: =IFERROR(__xludf.DUMMYFUNCTION("""COMPUTED_VALUE"""),"TERMINAL") -> TERMINAL | U1: =IFERROR(__xludf.DUMMYFUNCTION("""COMPUTED_VALUE"""),"PC") -> PC | V1: KETERANGAN | X1: =IFERROR(__xludf.DUMMYFUNCTION("{""NO"",""DATA BARU"",""TERMINAL"",""PC"";{SEQUENCE(COUNTIF($D$2:$D23550,3)),FILTER($A$2:$A23550,$D$2:$D23550=3),FILTER($B$2:$B23550,$D$2:$D23550=3),FILTER($D$2:$D23550,$D$2:$D23550=3)}}"),"NO") -> NO | Y1: =IFERROR(__xludf.DUMMYFUNCTION("""COMPUTED_VALUE"""),"DATA BARU") -> DATA BARU | Z1: =IFERROR(__xludf.DUMMYFUNCTION("""COMPUTED_VALUE"""),"TERMINAL") -> TERMINAL | AA1: =IFERROR(__xludf.DUMMYFUNCTION("""COMPUTED_VALUE"""),"PC") -> PC | AB1: KETERANGAN | AD1: =IFERROR(__xludf.DUMMYFUNCTION("{""NO"",""DATA BARU"",""TERMINAL"",""PC"";{SEQUENCE(COUNTIF($D$2:$D23550,4)),FILTER($A$2:$A23550,$D$2:$D23550=4),FILTER($B$2:$B23550,$D$2:$D23550=4),FILTER($D$2:$D23550,$D$2:$D23550=4)}}"),"NO") -> NO | AE1: =IFERROR(__xludf.DUMMYFUNCTION("""COMPUTED_VALUE"""),"DATA BARU") -> DATA BARU | AF1: =IFERROR(__xludf.DUMMYFUNCTION("""COMPUTED_VALUE"""),"TERMINAL") -> TERMINAL | AG1: =IFERROR(__xludf.DUMMYFUNCTION("""COMPUTED_VALUE"""),"PC") -> PC | AH1: KETERANGAN | AJ1: =IFERROR(__xludf.DUMMYFUNCTION("{""NO"",""DATA BARU"",""TERMINAL"",""PC"";{SEQUENCE(COUNTIF($D$2:$D23550,5)),FILTER($A$2:$A23550,$D$2:$D23550=5),FILTER($B$2:$B23550,$D$2:$D23550=5),FILTER($D$2:$D23550,$D$2:$D23550=5)}}"),"NO") -> NO | AK1: =IFERROR(__xludf.DUMMYFUNCTION("""COMPUTED_VALUE"""),"DATA BARU") -> DATA BARU | AL1: =IFERROR(__xludf.DUMMYFUNCTION("""COMPUTED_VALUE"""),"TERMINAL") -> TERMINAL | AM1: =IFERROR(__xludf.DUMMYFUNCTION("""COMPUTED_VALUE"""),"PC") -> PC | AN1: KETERANGAN | AP1: =IFERROR(__xludf.DUMMYFUNCTION("{""NO"",""DATA BARU"",""TERMINAL"",""PC"";{SEQUENCE(COUNTIF($D$2:$D23550,6)),FILTER($A$2:$A23550,$D$2:$D23550=6),FILTER($B$2:$B23550,$D$2:$D23550=6),FILTER($D$2:$D23550,$D$2:$D23550=6)}}"),"NO") -> NO | AQ1: =IFERROR(__xludf.DUMMYFUNCTION("""COMPUTED_VALUE"""),"DATA BARU") -> DATA BARU | AR1: =IFERROR(__xludf.DUMMYFUNCTION("""COMPUTED_VALUE"""),"TERMINAL") -> TERMINAL | AS1: =IFERROR(__xludf.DUMMYFUNCTION("""COMPUTED_VALUE"""),"PC") -> PC | AT1: KETERANGAN | AV1: ='KENDARAAN P1'!A:A -> NOPOL
A2: =IFERROR(__xludf.DUMMYFUNCTION("""COMPUTED_VALUE"""),"AD 9780 AB") -> AD 9780 AB | B2: =IFERROR(__xludf.DUMMYFUNCTION("""COMPUTED_VALUE"""),"TLPG LOMBOK") -> TLPG LOMBOK | C2: =IFERROR(__xludf.DUMMYFUNCTION("""COMPUTED_VALUE"""),1.0) -> 1 | D2: 2 | E2: SPPBE-PT. Lombok Putra Gas | G2: 1 | H2: =IFERROR(__xludf.DUMMYFUNCTION("SORT(FILTER({A2:A23550,B2:B23550,D2:D23550},D2:D23550<>""""),3,TRUE)"),"AE 8018 UG") -> AE 8018 UG | I2: =IFERROR(__xludf.DUMMYFUNCTION("""COMPUTED_VALUE"""),"TLPG TJ PERAK") -> TLPG TJ PERAK | J2: =IFERROR(__xludf.DUMMYFUNCTION("""COMPUTED_VALUE"""),1.0) -> 1 | L2: =IFERROR(__xludf.DUMMYFUNCTION("""COMPUTED_VALUE"""),1.0) -> 1 | M2: =IFERROR(__xludf.DUMMYFUNCTION("""COMPUTED_VALUE"""),"AE 8018 UG") -> AE 8018 UG | N2: =IFERROR(__xludf.DUMMYFUNCTION("""COMPUTED_VALUE"""),"TLPG TJ PERAK") -> TLPG TJ PERAK | O2: =IFERROR(__xludf.DUMMYFUNCTION("""COMPUTED_VALUE"""),1.0) -> 1 | P2: {=IF(M2:M29="","",IFERROR(VLOOKUP(M2:M29,$A$2:$E23550,5,FALSE),"Data Company Belum Ada"))} -> PT MADIUNI ELPIJI | R2: =IFERROR(__xludf.DUMMYFUNCTION("""COMPUTED_VALUE"""),1.0) -> 1 | S2: =IFERROR(__xludf.DUMMYFUNCTION("""COMPUTED_VALUE"""),"AD 9780 AB") -> AD 9780 AB | T2: =IFERROR(__xludf.DUMMYFUNCTION("""COMPUTED_VALUE"""),"TLPG LOMBOK") -> TLPG LOMBOK | U2: =IFERROR(__xludf.DUMMYFUNCTION("""COMPUTED_VALUE"""),2.0) -> 2 | V2: {=IF(S2:S29="","",IFERROR(VLOOKUP(S2:S29,$A$2:$E23550,5,FALSE),"Data Company Belum Ada"))} -> SPPBE-PT. Lombok Putra Gas | X2: =IFERROR(__xludf.DUMMYFUNCTION("""COMPUTED_VALUE"""),1.0) -> 1 | Y2: =IFERROR(__xludf.DUMMYFUNCTION("""COMPUTED_VALUE"""),"AG 8093 EI") -> AG 8093 EI | Z2: =IFERROR(__xludf.DUMMYFUNCTION("""COMPUTED_VALUE"""),"TLPG MEM GRESIK") -> TLPG MEM GRESIK | AA2: =IFERROR(__xludf.DUMMYFUNCTION("""COMPUTED_VALUE"""),3.0) -> 3 | AB2: {=IF(Y2:Y29="","",IFERROR(VLOOKUP(Y2:Y29,$A$2:$E23550,5,FALSE),"Data Company Belum Ada"))} -> PT RADIMA JAYA KEDIRI | AD2: =IFERROR(__xludf.DUMMYFUNCTION("""COMPUTED_VALUE"""),1.0) -> 1 | AE2: =IFERROR(__xludf.DUMMYFUNCTION("""COMPUTED_VALUE"""),"B 9713 SFU") -> B 9713 SFU | AF2: =IFERROR(__xludf.DUMMYFUNCTION("""COMPUTED_VALUE"""),"TLPG TJ WANGI") -> TLPG TJ WANGI | AG2: =IFERROR(__xludf.DUMMYFUNCTION("""COMPUTED_VALUE"""),4.0) -> 4 | AH2: {=IF(AE2:AE29="","",IFERROR(VLOOKUP(AE2:AE29,$A$2:$E23550,5,FALSE),"Data Company Belum Ada"))} -> PT PATRA NIAGA 1 | AJ2: =IFERROR(__xludf.DUMMYFUNCTION("""COMPUTED_VALUE"""),1.0) -> 1 | AK2: =IFERROR(__xludf.DUMMYFUNCTION("""COMPUTED_VALUE"""),"L 9155 UB") -> L 9155 UB | AL2: =IFERROR(__xludf.DUMMYFUNCTION("""COMPUTED_VALUE"""),"TLPG TJ PERAK") -> TLPG TJ PERAK | AM2: =IFERROR(__xludf.DUMMYFUNCTION("""COMPUTED_VALUE"""),5.0) -> 5 | AN2: {=IF(AK2:AK29="","",IFERROR(VLOOKUP(AK2:AK29,$A$2:$E23550,5,FALSE),"Data Company Belum Ada"))} -> PT AGUNG CATUR UTAMA GROUP | AP2: =IFERROR(__xludf.DUMMYFUNCTION("""COMPUTED_VALUE"""),1.0) -> 1 | AQ2: =IFERROR(__xludf.DUMMYFUNCTION("""COMPUTED_VALUE"""),"N 8782 UR") -> N 8782 UR | AR2: =IFERROR(__xludf.DUMMYFUNCTION("""COMPUTED_VALUE"""),"TLPG TJ WANGI") -> TLPG TJ WANGI | AS2: =IFERROR(__xludf.DUMMYFUNCTION("""COMPUTED_VALUE"""),6.0) -> 6 | AT2: {=IF(AQ2:AQ29="","",IFERROR(VLOOKUP(AQ2:AQ29,$A$2:$E23550,5,FALSE),"Data Company Belum Ada"))} -> Data Company Belum Ada | AV2: ='KENDARAAN P1'!A:A -> B 9080 SEI
A3: =IFERROR(__xludf.DUMMYFUNCTION("""COMPUTED_VALUE"""),"AE 8018 UG") -> AE 8018 UG | B3: =IFERROR(__xludf.DUMMYFUNCTION("""COMPUTED_VALUE"""),"TLPG TJ PERAK") -> TLPG TJ PERAK | C3: =IFERROR(__xludf.DUMMYFUNCTION("""COMPUTED_VALUE"""),1.0) -> 1 | D3: 1 | E3: PT MADIUNI ELPIJI | G3: 2 | H3: =IFERROR(__xludf.DUMMYFUNCTION("""COMPUTED_VALUE"""),"AE 8099 UT") -> AE 8099 UT | I3: =IFERROR(__xludf.DUMMYFUNCTION("""COMPUTED_VALUE"""),"TLPG TJ PERAK") -> TLPG TJ PERAK | J3: =IFERROR(__xludf.DUMMYFUNCTION("""COMPUTED_VALUE"""),1.0) -> 1 | L3: =IFERROR(__xludf.DUMMYFUNCTION("""COMPUTED_VALUE"""),2.0) -> 2 | M3: =IFERROR(__xludf.DUMMYFUNCTION("""COMPUTED_VALUE"""),"AE 8099 UT") -> AE 8099 UT | N3: =IFERROR(__xludf.DUMMYFUNCTION("""COMPUTED_VALUE"""),"TLPG TJ PERAK") -> TLPG TJ PERAK | O3: =IFERROR(__xludf.DUMMYFUNCTION("""COMPUTED_VALUE"""),1.0) -> 1 | P3: PT GAS ALAM BUMI REOG | R3: =IFERROR(__xludf.DUMMYFUNCTION("""COMPUTED_VALUE"""),2.0) -> 2 | S3: =IFERROR(__xludf.DUMMYFUNCTION("""COMPUTED_VALUE"""),"AE 8458 UF") -> AE 8458 UF | T3: =IFERROR(__xludf.DUMMYFUNCTION("""COMPUTED_VALUE"""),"TLPG TJ PERAK") -> TLPG TJ PERAK | U3: =IFERROR(__xludf.DUMMYFUNCTION("""COMPUTED_VALUE"""),2.0) -> 2 | V3: PT MADIUNI ELPIJI | X3: =IFERROR(__xludf.DUMMYFUNCTION("""COMPUTED_VALUE"""),2.0) -> 2 | Y3: =IFERROR(__xludf.DUMMYFUNCTION("""COMPUTED_VALUE"""),"AG 8016 UC") -> AG 8016 UC | Z3: =IFERROR(__xludf.DUMMYFUNCTION("""COMPUTED_VALUE"""),"TLPG TJ PERAK") -> TLPG TJ PERAK | AA3: =IFERROR(__xludf.DUMMYFUNCTION("""COMPUTED_VALUE"""),3.0) -> 3 | AB3: PT LIRBOYO INSAN GLOBAL | AD3: =IFERROR(__xludf.DUMMYFUNCTION("""COMPUTED_VALUE"""),2.0) -> 2 | AE3: =IFERROR(__xludf.DUMMYFUNCTION("""COMPUTED_VALUE"""),"B 9869 SFV") -> B 9869 SFV | AF3: =IFERROR(__xludf.DUMMYFUNCTION("""COMPUTED_VALUE"""),"TLPG MEM GRESIK") -> TLPG MEM GRESIK | AG3: =IFERROR(__xludf.DUMMYFUNCTION("""COMPUTED_VALUE"""),4.0) -> 4 | AH3: PT PATRA LOGISTIK | AJ3: =IFERROR(__xludf.DUMMYFUNCTION("""COMPUTED_VALUE"""),2.0) -> 2 | AK3: =IFERROR(__xludf.DUMMYFUNCTION("""COMPUTED_VALUE"""),"AG 8817 UT") -> AG 8817 UT | AL3: =IFERROR(__xludf.DUMMYFUNCTION("""COMPUTED_VALUE"""),"TLPG TJ PERAK") -> TLPG TJ PERAK | AM3: =IFERROR(__xludf.DUMMYFUNCTION("""COMPUTED_VALUE"""),5.0) -> 5 | AN3: PT GANGSAR SENTOSA PETROLIUM | AP3: =IFERROR(__xludf.DUMMYFUNCTION("""COMPUTED_VALUE"""),2.0) -> 2 | AQ3: =IFERROR(__xludf.DUMMYFUNCTION("""COMPUTED_VALUE"""),"DK 8837 HC") -> DK 8837 HC | AR3: =IFERROR(__xludf.DUMMYFUNCTION("""COMPUTED_VALUE"""),"TLPG MANGGIS") -> TLPG MANGGIS | AS3: =IFERROR(__xludf.DUMMYFUNCTION("""COMPUTED_VALUE"""),6.0) -> 6 | AT3: SPPBE-PT. Sembilan Semangat | AV3: ='KENDARAAN P1'!A:A -> B 9711 SFU
A4: =IFERROR(__xludf.DUMMYFUNCTION("""COMPUTED_VALUE"""),"AE 8099 UT") -> AE 8099 UT | B4: =IFERROR(__xludf.DUMMYFUNCTION("""COMPUTED_VALUE"""),"TLPG TJ PERAK") -> TLPG TJ PERAK | C4: =IFERROR(__xludf.DUMMYFUNCTION("""COMPUTED_VALUE"""),1.0) -> 1 | D4: 1 | E4: PT GAS ALAM BUMI REOG | G4: 3 | H4: =IFERROR(__xludf.DUMMYFUNCTION("""COMPUTED_VALUE"""),"AE 8175 UC") -> AE 8175 UC | I4: =IFERROR(__xludf.DUMMYFUNCTION("""COMPUTED_VALUE"""),"TLPG TJ PERAK") -> TLPG TJ PERAK | J4: =IFERROR(__xludf.DUMMYFUNCTION("""COMPUTED_VALUE"""),1.0) -> 1 | L4: =IFERROR(__xludf.DUMMYFUNCTION("""COMPUTED_VALUE"""),3.0) -> 3 | M4: =IFERROR(__xludf.DUMMYFUNCTION("""COMPUTED_VALUE"""),"AE 8175 UC") -> AE 8175 UC | N4: =IFERROR(__xludf.DUMMYFUNCTION("""COMPUTED_VALUE"""),"TLPG TJ PERAK") -> TLPG TJ PERAK | O4: =IFERROR(__xludf.DUMMYFUNCTION("""COMPUTED_VALUE"""),1.0) -> 1 | P4: PT MADIUNI ELPIJI | R4: =IFERROR(__xludf.DUMMYFUNCTION("""COMPUTED_VALUE"""),3.0) -> 3 | S4: =IFERROR(__xludf.DUMMYFUNCTION("""COMPUTED_VALUE"""),"AE 8459 UF") -> AE 8459 UF | T4: =IFERROR(__xludf.DUMMYFUNCTION("""COMPUTED_VALUE"""),"TLPG TJ PERAK") -> TLPG TJ PERAK | U4: =IFERROR(__xludf.DUMMYFUNCTION("""COMPUTED_VALUE"""),2.0) -> 2 | V4: PT MADIUNI ELPIJI | X4: =IFERROR(__xludf.DUMMYFUNCTION("""COMPUTED_VALUE"""),3.0) -> 3 | Y4: =IFERROR(__xludf.DUMMYFUNCTION("""COMPUTED_VALUE"""),"AG 8079 UZ") -> AG 8079 UZ | Z4: =IFERROR(__xludf.DUMMYFUNCTION("""COMPUTED_VALUE"""),"TLPG TJ PERAK") -> TLPG TJ PERAK | AA4: =IFERROR(__xludf.DUMMYFUNCTION("""COMPUTED_VALUE"""),3.0) -> 3 | AB4: PT DIAN EL HADA | AD4: =IFERROR(__xludf.DUMMYFUNCTION("""COMPUTED_VALUE"""),3.0) -> 3 | AE4: =IFERROR(__xludf.DUMMYFUNCTION("""COMPUTED_VALUE"""),"B 9884 SFU") -> B 9884 SFU | AF4: =IFERROR(__xludf.DUMMYFUNCTION("""COMPUTED_VALUE"""),"TLPG MEM GRESIK") -> TLPG MEM GRESIK | AG4: =IFERROR(__xludf.DUMMYFUNCTION("""COMPUTED_VALUE"""),4.0) -> 4 | AH4: PT PATRA NIAGA | AJ4: =IFERROR(__xludf.DUMMYFUNCTION("""COMPUTED_VALUE"""),3.0) -> 3 | AK4: =IFERROR(__xludf.DUMMYFUNCTION("""COMPUTED_VALUE"""),"AG 8818 UT") -> AG 8818 UT | AL4: =IFERROR(__xludf.DUMMYFUNCTION("""COMPUTED_VALUE"""),"TLPG TJ PERAK") -> TLPG TJ PERAK | AM4: =IFERROR(__xludf.DUMMYFUNCTION("""COMPUTED_VALUE"""),5.0) -> 5 | AN4: PT GANGSAR SENTOSA PETROLIUM | AP4: =IFERROR(__xludf.DUMMYFUNCTION("""COMPUTED_VALUE"""),3.0) -> 3 | AQ4: =IFERROR(__xludf.DUMMYFUNCTION("""COMPUTED_VALUE"""),"DR 8105 LJ") -> DR 8105 LJ | AR4: =IFERROR(__xludf.DUMMYFUNCTION("""COMPUTED_VALUE"""),"TLPG LOMBOK") -> TLPG LOMBOK | AS4: =IFERROR(__xludf.DUMMYFUNCTION("""COMPUTED_VALUE"""),6.0) -> 6 | AT4: SPPBE-PT. Anugrah Narwastu Raya | AV4: ='KENDARAAN P1'!A:A -> B 9089 SEI
A5: =IFERROR(__xludf.DUMMYFUNCTION("""COMPUTED_VALUE"""),"AE 8175 UC") -> AE 8175 UC | B5: =IFERROR(__xludf.DUMMYFUNCTION("""COMPUTED_VALUE"""),"TLPG TJ PERAK") -> TLPG TJ PERAK | C5: =IFERROR(__xludf.DUMMYFUNCTION("""COMPUTED_VALUE"""),1.0) -> 1 | D5: 1 | E5: PT MADIUNI ELPIJI | G5: 4 | H5: =IFERROR(__xludf.DUMMYFUNCTION("""COMPUTED_VALUE"""),"AE 8518 UJ") -> AE 8518 UJ | I5: =IFERROR(__xludf.DUMMYFUNCTION("""COMPUTED_VALUE"""),"TLPG TJ PERAK") -> TLPG TJ PERAK | J5: =IFERROR(__xludf.DUMMYFUNCTION("""COMPUTED_VALUE"""),1.0) -> 1 | L5: =IFERROR(__xludf.DUMMYFUNCTION("""COMPUTED_VALUE"""),4.0) -> 4 | M5: =IFERROR(__xludf.DUMMYFUNCTION("""COMPUTED_VALUE"""),"AE 8518 UJ") -> AE 8518 UJ | N5: =IFERROR(__xludf.DUMMYFUNCTION("""COMPUTED_VALUE"""),"TLPG TJ PERAK") -> TLPG TJ PERAK | O5: =IFERROR(__xludf.DUMMYFUNCTION("""COMPUTED_VALUE"""),1.0) -> 1 | P5: PT NUR WISTARA ABADI | R5: =IFERROR(__xludf.DUMMYFUNCTION("""COMPUTED_VALUE"""),4.0) -> 4 | S5: =IFERROR(__xludf.DUMMYFUNCTION("""COMPUTED_VALUE"""),"AE 8835 UQ") -> AE 8835 UQ | T5: =IFERROR(__xludf.DUMMYFUNCTION("""COMPUTED_VALUE"""),"TLPG TJ PERAK") -> TLPG TJ PERAK | U5: =IFERROR(__xludf.DUMMYFUNCTION("""COMPUTED_VALUE"""),2.0) -> 2 | V5: PT SEKAWAN GAS NUSA | X5: =IFERROR(__xludf.DUMMYFUNCTION("""COMPUTED_VALUE"""),4.0) -> 4 | Y5: =IFERROR(__xludf.DUMMYFUNCTION("""COMPUTED_VALUE"""),"AG 8086 UF") -> AG 8086 UF | Z5: =IFERROR(__xludf.DUMMYFUNCTION("""COMPUTED_VALUE"""),"TLPG TJ PERAK") -> TLPG TJ PERAK | AA5: =IFERROR(__xludf.DUMMYFUNCTION("""COMPUTED_VALUE"""),3.0) -> 3 | AB5: PT DIAN RAMA GAS | AD5: =IFERROR(__xludf.DUMMYFUNCTION("""COMPUTED_VALUE"""),4.0) -> 4 | AE5: =IFERROR(__xludf.DUMMYFUNCTION("""COMPUTED_VALUE"""),"DK 8146 BZ") -> DK 8146 BZ | AF5: =IFERROR(__xludf.DUMMYFUNCTION("""COMPUTED_VALUE"""),"TLPG MANGGIS") -> TLPG MANGGIS | AG5: =IFERROR(__xludf.DUMMYFUNCTION("""COMPUTED_VALUE"""),4.0) -> 4 | AH5: SPPBE-PT. Pande Agung Dewata | AJ5: =IFERROR(__xludf.DUMMYFUNCTION("""COMPUTED_VALUE"""),4.0) -> 4 | AK5: =IFERROR(__xludf.DUMMYFUNCTION("""COMPUTED_VALUE"""),"B 9088 SEI") -> B 9088 SEI | AL5: =IFERROR(__xludf.DUMMYFUNCTION("""COMPUTED_VALUE"""),"TLPG MEM GRESIK") -> TLPG MEM GRESIK | AM5: =IFERROR(__xludf.DUMMYFUNCTION("""COMPUTED_VALUE"""),5.0) -> 5 | AN5: PT PATRA NIAGA | AP5: =IFERROR(__xludf.DUMMYFUNCTION("""COMPUTED_VALUE"""),4.0) -> 4 | AQ5: =IFERROR(__xludf.DUMMYFUNCTION("""COMPUTED_VALUE"""),"P 8176 UW") -> P 8176 UW | AR5: =IFERROR(__xludf.DUMMYFUNCTION("""COMPUTED_VALUE"""),"TLPG TJ WANGI") -> TLPG TJ WANGI | AS5: =IFERROR(__xludf.DUMMYFUNCTION("""COMPUTED_VALUE"""),6.0) -> 6 | AT5: PT ARGOPURO MAJU SUKSES | AV5: ='KENDARAAN P1'!A:A -> B 9098 SEI
A6: =IFERROR(__xludf.DUMMYFUNCTION("""COMPUTED_VALUE"""),"AE 8458 UF") -> AE 8458 UF | B6: =IFERROR(__xludf.DUMMYFUNCTION("""COMPUTED_VALUE"""),"TLPG TJ PERAK") -> TLPG TJ PERAK | C6: =IFERROR(__xludf.DUMMYFUNCTION("""COMPUTED_VALUE"""),1.0) -> 1 | D6: 2 | E6: PT MADIUNI ELPIJI | G6: 5 | H6: =IFERROR(__xludf.DUMMYFUNCTION("""COMPUTED_VALUE"""),"AE 8546 UJ") -> AE 8546 UJ | I6: =IFERROR(__xludf.DUMMYFUNCTION("""COMPUTED_VALUE"""),"TLPG TJ PERAK") -> TLPG TJ PERAK | J6: =IFERROR(__xludf.DUMMYFUNCTION("""COMPUTED_VALUE"""),1.0) -> 1 | L6: =IFERROR(__xludf.DUMMYFUNCTION("""COMPUTED_VALUE"""),5.0) -> 5 | M6: =IFERROR(__xludf.DUMMYFUNCTION("""COMPUTED_VALUE"""),"AE 8546 UJ") -> AE 8546 UJ | N6: =IFERROR(__xludf.DUMMYFUNCTION("""COMPUTED_VALUE"""),"TLPG TJ PERAK") -> TLPG TJ PERAK | O6: =IFERROR(__xludf.DUMMYFUNCTION("""COMPUTED_VALUE"""),1.0) -> 1 | P6: PT NUR WISTARA ABADI | R6: =IFERROR(__xludf.DUMMYFUNCTION("""COMPUTED_VALUE"""),5.0) -> 5 | S6: =IFERROR(__xludf.DUMMYFUNCTION("""COMPUTED_VALUE"""),"AG 9876 RK") -> AG 9876 RK | T6: =IFERROR(__xludf.DUMMYFUNCTION("""COMPUTED_VALUE"""),"TLPG MEM GRESIK") -> TLPG MEM GRESIK | U6: =IFERROR(__xludf.DUMMYFUNCTION("""COMPUTED_VALUE"""),2.0) -> 2 | V6: PT BINTANG CIPTA PERSADA | X6: =IFERROR(__xludf.DUMMYFUNCTION("""COMPUTED_VALUE"""),5.0) -> 5 | Y6: =IFERROR(__xludf.DUMMYFUNCTION("""COMPUTED_VALUE"""),"AG 8087 UF") -> AG 8087 UF | Z6: =IFERROR(__xludf.DUMMYFUNCTION("""COMPUTED_VALUE"""),"TLPG TJ PERAK") -> TLPG TJ PERAK | AA6: =IFERROR(__xludf.DUMMYFUNCTION("""COMPUTED_VALUE"""),3.0) -> 3 | AB6: PT DIAN RAMA GAS | AD6: =IFERROR(__xludf.DUMMYFUNCTION("""COMPUTED_VALUE"""),5.0) -> 5 | AE6: =IFERROR(__xludf.DUMMYFUNCTION("""COMPUTED_VALUE"""),"L 9837 UJ") -> L 9837 UJ | AF6: =IFERROR(__xludf.DUMMYFUNCTION("""COMPUTED_VALUE"""),"TLPG MEM GRESIK") -> TLPG MEM GRESIK | AG6: =IFERROR(__xludf.DUMMYFUNCTION("""COMPUTED_VALUE"""),4.0) -> 4 | AH6: PT PATRA NIAGA | AJ6: =IFERROR(__xludf.DUMMYFUNCTION("""COMPUTED_VALUE"""),5.0) -> 5 | AK6: =IFERROR(__xludf.DUMMYFUNCTION("""COMPUTED_VALUE"""),"B 9882 SFU") -> B 9882 SFU | AL6: =IFERROR(__xludf.DUMMYFUNCTION("""COMPUTED_VALUE"""),"TLPG MEM GRESIK") -> TLPG MEM GRESIK | AM6: =IFERROR(__xludf.DUMMYFUNCTION("""COMPUTED_VALUE"""),5.0) -> 5 | AN6: PT PATRA NIAGA | AP6: =IFERROR(__xludf.DUMMYFUNCTION("""COMPUTED_VALUE"""),5.0) -> 5 | AQ6: =IFERROR(__xludf.DUMMYFUNCTION("""COMPUTED_VALUE"""),"W 9170 PD") -> W 9170 PD | AR6: =IFERROR(__xludf.DUMMYFUNCTION("""COMPUTED_VALUE"""),"TLPG TJ PERAK") -> TLPG TJ PERAK | AS6: =IFERROR(__xludf.DUMMYFUNCTION("""COMPUTED_VALUE"""),6.0) -> 6 | AT6: PT NAWA PELITA RAYA | AV6: ='KENDARAAN P1'!A:A -> B 9099 SEI
A7: =IFERROR(__xludf.DUMMYFUNCTION("""COMPUTED_VALUE"""),"AE 8459 UF") -> AE 8459 UF | B7: =IFERROR(__xludf.DUMMYFUNCTION("""COMPUTED_VALUE"""),"TLPG TJ PERAK") -> TLPG TJ PERAK | C7: =IFERROR(__xludf.DUMMYFUNCTION("""COMPUTED_VALUE"""),1.0) -> 1 | D7: 2 | E7: PT MADIUNI ELPIJI | G7: 6 | H7: =IFERROR(__xludf.DUMMYFUNCTION("""COMPUTED_VALUE"""),"AE 8639 UP") -> AE 8639 UP | I7: =IFERROR(__xludf.DUMMYFUNCTION("""COMPUTED_VALUE"""),"TLPG TJ PERAK") -> TLPG TJ PERAK | J7: =IFERROR(__xludf.DUMMYFUNCTION("""COMPUTED_VALUE"""),1.0) -> 1 | L7: =IFERROR(__xludf.DUMMYFUNCTION("""COMPUTED_VALUE"""),6.0) -> 6 | M7: =IFERROR(__xludf.DUMMYFUNCTION("""COMPUTED_VALUE"""),"AE 8639 UP") -> AE 8639 UP | N7: =IFERROR(__xludf.DUMMYFUNCTION("""COMPUTED_VALUE"""),"TLPG TJ PERAK") -> TLPG TJ PERAK | O7: =IFERROR(__xludf.DUMMYFUNCTION("""COMPUTED_VALUE"""),1.0) -> 1 | P7: PT TRISINDO ADIKAMULIA | R7: =IFERROR(__xludf.DUMMYFUNCTION("""COMPUTED_VALUE"""),6.0) -> 6 | S7: =IFERROR(__xludf.DUMMYFUNCTION("""COMPUTED_VALUE"""),"AD 9838 AB") -> AD 9838 AB | T7: =IFERROR(__xludf.DUMMYFUNCTION("""COMPUTED_VALUE"""),"TLPG LOMBOK") -> TLPG LOMBOK | U7: =IFERROR(__xludf.DUMMYFUNCTION("""COMPUTED_VALUE"""),2.0) -> 2 | V7: SPPBE-PT. Lombok Putra Gas | X7: =IFERROR(__xludf.DUMMYFUNCTION("""COMPUTED_VALUE"""),6.0) -> 6 | Y7: =IFERROR(__xludf.DUMMYFUNCTION("""COMPUTED_VALUE"""),"AG 8088 UF") -> AG 8088 UF | Z7: =IFERROR(__xludf.DUMMYFUNCTION("""COMPUTED_VALUE"""),"TLPG TJ PERAK") -> TLPG TJ PERAK | AA7: =IFERROR(__xludf.DUMMYFUNCTION("""COMPUTED_VALUE"""),3.0) -> 3 | AB7: PT DIAN RAMA GAS | AD7: =IFERROR(__xludf.DUMMYFUNCTION("""COMPUTED_VALUE"""),6.0) -> 6 | AE7: =IFERROR(__xludf.DUMMYFUNCTION("""COMPUTED_VALUE"""),"P 8277 UG") -> P 8277 UG | AF7: =IFERROR(__xludf.DUMMYFUNCTION("""COMPUTED_VALUE"""),"TLPG TJ WANGI") -> TLPG TJ WANGI | AG7: =IFERROR(__xludf.DUMMYFUNCTION("""COMPUTED_VALUE"""),4.0) -> 4 | AH7: Data Company Belum Ada | AJ7: =IFERROR(__xludf.DUMMYFUNCTION("""COMPUTED_VALUE"""),6.0) -> 6 | AK7: =IFERROR(__xludf.DUMMYFUNCTION("""COMPUTED_VALUE"""),"B 9883 SFU") -> B 9883 SFU | AL7: =IFERROR(__xludf.DUMMYFUNCTION("""COMPUTED_VALUE"""),"TLPG MEM GRESIK") -> TLPG MEM GRESIK | AM7: =IFERROR(__xludf.DUMMYFUNCTION("""COMPUTED_VALUE"""),5.0) -> 5 | AN7: PT PATRA NIAGA | AP7: =IFERROR(__xludf.DUMMYFUNCTION("""COMPUTED_VALUE"""),6.0) -> 6 | AQ7: =IFERROR(__xludf.DUMMYFUNCTION("""COMPUTED_VALUE"""),"B 9717 SFU") -> B 9717 SFU | AR7: =IFERROR(__xludf.DUMMYFUNCTION("""COMPUTED_VALUE"""),"TLPG MEM GRESIK") -> TLPG MEM GRESIK | AS7: =IFERROR(__xludf.DUMMYFUNCTION("""COMPUTED_VALUE"""),6.0) -> 6 | AT7: PT PATRA NIAGA | AV7: ='KENDARAAN P1'!A:A -> B 9105 SEI
A8: =IFERROR(__xludf.DUMMYFUNCTION("""COMPUTED_VALUE"""),"AE 8518 UJ") -> AE 8518 UJ | B8: =IFERROR(__xludf.DUMMYFUNCTION("""COMPUTED_VALUE"""),"TLPG TJ PERAK") -> TLPG TJ PERAK | C8: =IFERROR(__xludf.DUMMYFUNCTION("""COMPUTED_VALUE"""),1.0) -> 1 | D8: 1 | E8: PT NUR WISTARA ABADI | G8: 7 | H8: =IFERROR(__xludf.DUMMYFUNCTION("""COMPUTED_VALUE"""),"AE 8641 UP") -> AE 8641 UP | I8: =IFERROR(__xludf.DUMMYFUNCTION("""COMPUTED_VALUE"""),"TLPG TJ PERAK") -> TLPG TJ PERAK | J8: =IFERROR(__xludf.DUMMYFUNCTION("""COMPUTED_VALUE"""),1.0) -> 1 | L8: =IFERROR(__xludf.DUMMYFUNCTION("""COMPUTED_VALUE"""),7.0) -> 7 | M8: =IFERROR(__xludf.DUMMYFUNCTION("""COMPUTED_VALUE"""),"AE 8641 UP") -> AE 8641 UP | N8: =IFERROR(__xludf.DUMMYFUNCTION("""COMPUTED_VALUE"""),"TLPG TJ PERAK") -> TLPG TJ PERAK | O8: =IFERROR(__xludf.DUMMYFUNCTION("""COMPUTED_VALUE"""),1.0) -> 1 | P8: PT TRISINDO ADIKAMULIA | R8: =IFERROR(__xludf.DUMMYFUNCTION("""COMPUTED_VALUE"""),7.0) -> 7 | S8: =IFERROR(__xludf.DUMMYFUNCTION("""COMPUTED_VALUE"""),"AD 9877 AB") -> AD 9877 AB | T8: =IFERROR(__xludf.DUMMYFUNCTION("""COMPUTED_VALUE"""),"TLPG LOMBOK") -> TLPG LOMBOK | U8: =IFERROR(__xludf.DUMMYFUNCTION("""COMPUTED_VALUE"""),2.0) -> 2 | V8: SPPBE-PT. Lombok Putra Gas | X8: =IFERROR(__xludf.DUMMYFUNCTION("""COMPUTED_VALUE"""),7.0) -> 7 | Y8: =IFERROR(__xludf.DUMMYFUNCTION("""COMPUTED_VALUE"""),"AG 8106 UC") -> AG 8106 UC | Z8: =IFERROR(__xludf.DUMMYFUNCTION("""COMPUTED_VALUE"""),"TLPG TJ PERAK") -> TLPG TJ PERAK | AA8: =IFERROR(__xludf.DUMMYFUNCTION("""COMPUTED_VALUE"""),3.0) -> 3 | AB8: PT LIRBOYO INSAN GLOBAL | AD8: =IFERROR(__xludf.DUMMYFUNCTION("""COMPUTED_VALUE"""),7.0) -> 7 | AE8: =IFERROR(__xludf.DUMMYFUNCTION("""COMPUTED_VALUE"""),"AG 8223 LB") -> AG 8223 LB | AF8: =IFERROR(__xludf.DUMMYFUNCTION("""COMPUTED_VALUE"""),"TLPG TJ PERAK") -> TLPG TJ PERAK | AG8: =IFERROR(__xludf.DUMMYFUNCTION("""COMPUTED_VALUE"""),4.0) -> 4 | AH8: PT RAMA MANGGALA GAS | AJ8: =IFERROR(__xludf.DUMMYFUNCTION("""COMPUTED_VALUE"""),7.0) -> 7 | AK8: =IFERROR(__xludf.DUMMYFUNCTION("""COMPUTED_VALUE"""),"DK 8170 UB") -> DK 8170 UB | AL8: =IFERROR(__xludf.DUMMYFUNCTION("""COMPUTED_VALUE"""),"TLPG MANGGIS") -> TLPG MANGGIS | AM8: =IFERROR(__xludf.DUMMYFUNCTION("""COMPUTED_VALUE"""),5.0) -> 5 | AN8: PT. Ayu Sari Pertiwi | AP8: =IFERROR(__xludf.DUMMYFUNCTION("""COMPUTED_VALUE"""),7.0) -> 7 | AQ8: =IFERROR(__xludf.DUMMYFUNCTION("""COMPUTED_VALUE"""),"B 9881 SFU") -> B 9881 SFU | AR8: =IFERROR(__xludf.DUMMYFUNCTION("""COMPUTED_VALUE"""),"TLPG MEM GRESIK") -> TLPG MEM GRESIK | AS8: =IFERROR(__xludf.DUMMYFUNCTION("""COMPUTED_VALUE"""),6.0) -> 6 | AT8: PT PATRA NIAGA | AV8: ='KENDARAAN P1'!A:A -> B 9884 SFU
A9: =IFERROR(__xludf.DUMMYFUNCTION("""COMPUTED_VALUE"""),"AE 8546 UJ") -> AE 8546 UJ | B9: =IFERROR(__xludf.DUMMYFUNCTION("""COMPUTED_VALUE"""),"TLPG TJ PERAK") -> TLPG TJ PERAK | C9: =IFERROR(__xludf.DUMMYFUNCTION("""COMPUTED_VALUE"""),1.0) -> 1 | D9: 1 | E9: PT NUR WISTARA ABADI | G9: 8 | H9: =IFERROR(__xludf.DUMMYFUNCTION("""COMPUTED_VALUE"""),"AE 8642 UP") -> AE 8642 UP | I9: =IFERROR(__xludf.DUMMYFUNCTION("""COMPUTED_VALUE"""),"TLPG TJ PERAK") -> TLPG TJ PERAK | J9: =IFERROR(__xludf.DUMMYFUNCTION("""COMPUTED_VALUE"""),1.0) -> 1 | L9: =IFERROR(__xludf.DUMMYFUNCTION("""COMPUTED_VALUE"""),8.0) -> 8 | M9: =IFERROR(__xludf.DUMMYFUNCTION("""COMPUTED_VALUE"""),"AE 8642 UP") -> AE 8642 UP | N9: =IFERROR(__xludf.DUMMYFUNCTION("""COMPUTED_VALUE"""),"TLPG TJ PERAK") -> TLPG TJ PERAK | O9: =IFERROR(__xludf.DUMMYFUNCTION("""COMPUTED_VALUE"""),1.0) -> 1 | P9: PT TRISINDO ADIKAMULIA | R9: =IFERROR(__xludf.DUMMYFUNCTION("""COMPUTED_VALUE"""),8.0) -> 8 | S9: =IFERROR(__xludf.DUMMYFUNCTION("""COMPUTED_VALUE"""),"AE 8845 UT") -> AE 8845 UT | T9: =IFERROR(__xludf.DUMMYFUNCTION("""COMPUTED_VALUE"""),"TLPG TJ PERAK") -> TLPG TJ PERAK | U9: =IFERROR(__xludf.DUMMYFUNCTION("""COMPUTED_VALUE"""),2.0) -> 2 | V9: PT BUANA KARYA SURYA PRATAMA | X9: =IFERROR(__xludf.DUMMYFUNCTION("""COMPUTED_VALUE"""),8.0) -> 8 | Y9: =IFERROR(__xludf.DUMMYFUNCTION("""COMPUTED_VALUE"""),"AG 8126 UF") -> AG 8126 UF | Z9: =IFERROR(__xludf.DUMMYFUNCTION("""COMPUTED_VALUE"""),"TLPG TJ PERAK") -> TLPG TJ PERAK | AA9: =IFERROR(__xludf.DUMMYFUNCTION("""COMPUTED_VALUE"""),3.0) -> 3 | AB9: PT NARA RIZKA MANUNGGAL | AD9: =IFERROR(__xludf.DUMMYFUNCTION("""COMPUTED_VALUE"""),8.0) -> 8 | AE9: =IFERROR(__xludf.DUMMYFUNCTION("""COMPUTED_VALUE"""),"AG 8701 UO") -> AG 8701 UO | AF9: =IFERROR(__xludf.DUMMYFUNCTION("""COMPUTED_VALUE"""),"TLPG TJ PERAK") -> TLPG TJ PERAK | AG9: =IFERROR(__xludf.DUMMYFUNCTION("""COMPUTED_VALUE"""),4.0) -> 4 | AH9: PT MODERNA TEHNIK PERKASA | AJ9: =IFERROR(__xludf.DUMMYFUNCTION("""COMPUTED_VALUE"""),8.0) -> 8 | AK9: =IFERROR(__xludf.DUMMYFUNCTION("""COMPUTED_VALUE"""),"DK 8773 MG") -> DK 8773 MG | AL9: =IFERROR(__xludf.DUMMYFUNCTION("""COMPUTED_VALUE"""),"TLPG LOMBOK") -> TLPG LOMBOK | AM9: =IFERROR(__xludf.DUMMYFUNCTION("""COMPUTED_VALUE"""),5.0) -> 5 | AN9: SPPBE-PT. Harapan Jaya Utama | AP9: =IFERROR(__xludf.DUMMYFUNCTION("""COMPUTED_VALUE"""),8.0) -> 8 | AQ9: =IFERROR(__xludf.DUMMYFUNCTION("""COMPUTED_VALUE"""),"L 8121 UUA") -> L 8121 UUA | AR9: =IFERROR(__xludf.DUMMYFUNCTION("""COMPUTED_VALUE"""),"TLPG MEM GRESIK") -> TLPG MEM GRESIK | AS9: =IFERROR(__xludf.DUMMYFUNCTION("""COMPUTED_VALUE"""),6.0) -> 6 | AT9: PT UNIVERSAL ENERGY PRATAMA | AV9: ='KENDARAAN P1'!A:A -> B 9869 SFV
A10: =IFERROR(__xludf.DUMMYFUNCTION("""COMPUTED_VALUE"""),"AE 8639 UP") -> AE 8639 UP | B10: =IFERROR(__xludf.DUMMYFUNCTION("""COMPUTED_VALUE"""),"TLPG TJ PERAK") -> TLPG TJ PERAK | C10: =IFERROR(__xludf.DUMMYFUNCTION("""COMPUTED_VALUE"""),1.0) -> 1 | D10: 1 | E10: PT TRISINDO ADIKAMULIA | G10: 9 | H10: =IFERROR(__xludf.DUMMYFUNCTION("""COMPUTED_VALUE"""),"AE 9061 UJ") -> AE 9061 UJ | I10: =IFERROR(__xludf.DUMMYFUNCTION("""COMPUTED_VALUE"""),"TLPG TJ PERAK") -> TLPG TJ PERAK | J10: =IFERROR(__xludf.DUMMYFUNCTION("""COMPUTED_VALUE"""),1.0) -> 1 | L10: =IFERROR(__xludf.DUMMYFUNCTION("""COMPUTED_VALUE"""),9.0) -> 9 | M10: =IFERROR(__xludf.DUMMYFUNCTION("""COMPUTED_VALUE"""),"AE 9061 UJ") -> AE 9061 UJ | N10: =IFERROR(__xludf.DUMMYFUNCTION("""COMPUTED_VALUE"""),"TLPG TJ PERAK") -> TLPG TJ PERAK | O10: =IFERROR(__xludf.DUMMYFUNCTION("""COMPUTED_VALUE"""),1.0) -> 1 | P10: PT NUR WISTARA ABADI | R10: =IFERROR(__xludf.DUMMYFUNCTION("""COMPUTED_VALUE"""),9.0) -> 9 | S10: =IFERROR(__xludf.DUMMYFUNCTION("""COMPUTED_VALUE"""),"AE 8846 UT") -> AE 8846 UT | T10: =IFERROR(__xludf.DUMMYFUNCTION("""COMPUTED_VALUE"""),"TLPG TJ PERAK") -> TLPG TJ PERAK | U10: =IFERROR(__xludf.DUMMYFUNCTION("""COMPUTED_VALUE"""),2.0) -> 2 | V10: PT BUANA KARYA SURYA PRATAMA | X10: =IFERROR(__xludf.DUMMYFUNCTION("""COMPUTED_VALUE"""),9.0) -> 9 | Y10: =IFERROR(__xludf.DUMMYFUNCTION("""COMPUTED_VALUE"""),"AG 8128 UF") -> AG 8128 UF | Z10: =IFERROR(__xludf.DUMMYFUNCTION("""COMPUTED_VALUE"""),"TLPG TJ PERAK") -> TLPG TJ PERAK | AA10: =IFERROR(__xludf.DUMMYFUNCTION("""COMPUTED_VALUE"""),3.0) -> 3 | AB10: PT NARA RIZKA MANUNGGAL | AD10: =IFERROR(__xludf.DUMMYFUNCTION("""COMPUTED_VALUE"""),9.0) -> 9 | AE10: =IFERROR(__xludf.DUMMYFUNCTION("""COMPUTED_VALUE"""),"AG 8702 UO") -> AG 8702 UO | AF10: =IFERROR(__xludf.DUMMYFUNCTION("""COMPUTED_VALUE"""),"TLPG TJ PERAK") -> TLPG TJ PERAK | AG10: =IFERROR(__xludf.DUMMYFUNCTION("""COMPUTED_VALUE"""),4.0) -> 4 | AH10: PT MODERNA TEHNIK PERKASA | AJ10: =IFERROR(__xludf.DUMMYFUNCTION("""COMPUTED_VALUE"""),9.0) -> 9 | AK10: =IFERROR(__xludf.DUMMYFUNCTION("""COMPUTED_VALUE"""),"N 8857 UR") -> N 8857 UR | AL10: =IFERROR(__xludf.DUMMYFUNCTION("""COMPUTED_VALUE"""),"TLPG TJ WANGI") -> TLPG TJ WANGI | AM10: =IFERROR(__xludf.DUMMYFUNCTION("""COMPUTED_VALUE"""),5.0) -> 5 | AN10: PT PATRA NIAGA | AP10: =IFERROR(__xludf.DUMMYFUNCTION("""COMPUTED_VALUE"""),9.0) -> 9 | AQ10: =IFERROR(__xludf.DUMMYFUNCTION("""COMPUTED_VALUE"""),"L 8892 UU") -> L 8892 UU | AR10: =IFERROR(__xludf.DUMMYFUNCTION("""COMPUTED_VALUE"""),"TLPG TJ PERAK") -> TLPG TJ PERAK | AS10: =IFERROR(__xludf.DUMMYFUNCTION("""COMPUTED_VALUE"""),6.0) -> 6 | AT10: PT MUTUAL MAXEL | AV10: ='KENDARAAN P1'!A:A -> B 9115 SEI
A11: =IFERROR(__xludf.DUMMYFUNCTION("""COMPUTED_VALUE"""),"AE 8641 UP") -> AE 8641 UP | B11: =IFERROR(__xludf.DUMMYFUNCTION("""COMPUTED_VALUE"""),"TLPG TJ PERAK") -> TLPG TJ PERAK | C11: =IFERROR(__xludf.DUMMYFUNCTION("""COMPUTED_VALUE"""),1.0) -> 1 | D11: 1 | E11: PT TRISINDO ADIKAMULIA | G11: 10 | H11: =IFERROR(__xludf.DUMMYFUNCTION("""COMPUTED_VALUE"""),"B 9080 SEI") -> B 9080 SEI | I11: =IFERROR(__xludf.DUMMYFUNCTION("""COMPUTED_VALUE"""),"TLPG TJ WANGI") -> TLPG TJ WANGI | J11: =IFERROR(__xludf.DUMMYFUNCTION("""COMPUTED_VALUE"""),1.0) -> 1 | L11: =IFERROR(__xludf.DUMMYFUNCTION("""COMPUTED_VALUE"""),10.0) -> 10 | M11: =IFERROR(__xludf.DUMMYFUNCTION("""COMPUTED_VALUE"""),"B 9080 SEI") -> B 9080 SEI | N11: =IFERROR(__xludf.DUMMYFUNCTION("""COMPUTED_VALUE"""),"TLPG TJ WANGI") -> TLPG TJ WANGI | O11: =IFERROR(__xludf.DUMMYFUNCTION("""COMPUTED_VALUE"""),1.0) -> 1 | P11: PT PATRA NIAGA 1 | R11: =IFERROR(__xludf.DUMMYFUNCTION("""COMPUTED_VALUE"""),10.0) -> 10 | S11: =IFERROR(__xludf.DUMMYFUNCTION("""COMPUTED_VALUE"""),"AE 8857 UT") -> AE 8857 UT | T11: =IFERROR(__xludf.DUMMYFUNCTION("""COMPUTED_VALUE"""),"TLPG TJ PERAK") -> TLPG TJ PERAK | U11: =IFERROR(__xludf.DUMMYFUNCTION("""COMPUTED_VALUE"""),2.0) -> 2 | V11: PT BUANA KARYA SURYA PRATAMA | X11: =IFERROR(__xludf.DUMMYFUNCTION("""COMPUTED_VALUE"""),10.0) -> 10 | Y11: =IFERROR(__xludf.DUMMYFUNCTION("""COMPUTED_VALUE"""),"AG 8129 UF") -> AG 8129 UF | Z11: =IFERROR(__xludf.DUMMYFUNCTION("""COMPUTED_VALUE"""),"TLPG TJ PERAK") -> TLPG TJ PERAK | AA11: =IFERROR(__xludf.DUMMYFUNCTION("""COMPUTED_VALUE"""),3.0) -> 3 | AB11: PT NARA RIZKA MANUNGGAL | AD11: =IFERROR(__xludf.DUMMYFUNCTION("""COMPUTED_VALUE"""),10.0) -> 10 | AE11: =IFERROR(__xludf.DUMMYFUNCTION("""COMPUTED_VALUE"""),"AG 8717 UO") -> AG 8717 UO | AF11: =IFERROR(__xludf.DUMMYFUNCTION("""COMPUTED_VALUE"""),"TLPG TJ PERAK") -> TLPG TJ PERAK | AG11: =IFERROR(__xludf.DUMMYFUNCTION("""COMPUTED_VALUE"""),4.0) -> 4 | AH11: PT MODERNA TEHNIK PERKASA | AJ11: =IFERROR(__xludf.DUMMYFUNCTION("""COMPUTED_VALUE"""),10.0) -> 10 | AK11: =IFERROR(__xludf.DUMMYFUNCTION("""COMPUTED_VALUE"""),"N 9287 UN") -> N 9287 UN | AL11: =IFERROR(__xludf.DUMMYFUNCTION("""COMPUTED_VALUE"""),"TLPG TJ WANGI") -> TLPG TJ WANGI | AM11: =IFERROR(__xludf.DUMMYFUNCTION("""COMPUTED_VALUE"""),5.0) -> 5 | AN11: PT HAKAMINDO PETROCHEM | AP11: =IFERROR(__xludf.DUMMYFUNCTION("""COMPUTED_VALUE"""),10.0) -> 10 | AQ11: =IFERROR(__xludf.DUMMYFUNCTION("""COMPUTED_VALUE"""),"L 8973 UU") -> L 8973 UU | AR11: =IFERROR(__xludf.DUMMYFUNCTION("""COMPUTED_VALUE"""),"TLPG TJ PERAK") -> TLPG TJ PERAK | AS11: =IFERROR(__xludf.DUMMYFUNCTION("""COMPUTED_VALUE"""),6.0) -> 6 | AT11: PT GOENADI GASINDO PRATAMA | AV11: ='KENDARAAN P1'!A:A -> B 9712 SFU
A12: =IFERROR(__xludf.DUMMYFUNCTION("""COMPUTED_VALUE"""),"AE 8642 UP") -> AE 8642 UP | B12: =IFERROR(__xludf.DUMMYFUNCTION("""COMPUTED_VALUE"""),"TLPG TJ PERAK") -> TLPG TJ PERAK | C12: =IFERROR(__xludf.DUMMYFUNCTION("""COMPUTED_VALUE"""),1.0) -> 1 | D12: 1 | E12: PT TRISINDO ADIKAMULIA | G12: 11 | H12: =IFERROR(__xludf.DUMMYFUNCTION("""COMPUTED_VALUE"""),"B 9089 SEI") -> B 9089 SEI | I12: =IFERROR(__xludf.DUMMYFUNCTION("""COMPUTED_VALUE"""),"TLPG MEM GRESIK") -> TLPG MEM GRESIK | J12: =IFERROR(__xludf.DUMMYFUNCTION("""COMPUTED_VALUE"""),1.0) -> 1 | L12: =IFERROR(__xludf.DUMMYFUNCTION("""COMPUTED_VALUE"""),11.0) -> 11 | M12: =IFERROR(__xludf.DUMMYFUNCTION("""COMPUTED_VALUE"""),"B 9089 SEI") -> B 9089 SEI | N12: =IFERROR(__xludf.DUMMYFUNCTION("""COMPUTED_VALUE"""),"TLPG MEM GRESIK") -> TLPG MEM GRESIK | O12: =IFERROR(__xludf.DUMMYFUNCTION("""COMPUTED_VALUE"""),1.0) -> 1 | P12: PT PATRA NIAGA | R12: =IFERROR(__xludf.DUMMYFUNCTION("""COMPUTED_VALUE"""),11.0) -> 11 | S12: =IFERROR(__xludf.DUMMYFUNCTION("""COMPUTED_VALUE"""),"AE 9401 UJ") -> AE 9401 UJ | T12: =IFERROR(__xludf.DUMMYFUNCTION("""COMPUTED_VALUE"""),"TLPG TJ PERAK") -> TLPG TJ PERAK | U12: =IFERROR(__xludf.DUMMYFUNCTION("""COMPUTED_VALUE"""),2.0) -> 2 | V12: PT SUMINAR MITRAGAS SELARAS | X12: =IFERROR(__xludf.DUMMYFUNCTION("""COMPUTED_VALUE"""),11.0) -> 11 | Y12: =IFERROR(__xludf.DUMMYFUNCTION("""COMPUTED_VALUE"""),"AG 8152 UL") -> AG 8152 UL | Z12: =IFERROR(__xludf.DUMMYFUNCTION("""COMPUTED_VALUE"""),"TLPG TJ PERAK") -> TLPG TJ PERAK | AA12: =IFERROR(__xludf.DUMMYFUNCTION("""COMPUTED_VALUE"""),3.0) -> 3 | AB12: PT RAMA MANGGALA GAS | AD12: =IFERROR(__xludf.DUMMYFUNCTION("""COMPUTED_VALUE"""),11.0) -> 11 | AE12: =IFERROR(__xludf.DUMMYFUNCTION("""COMPUTED_VALUE"""),"AG 8817 UK") -> AG 8817 UK | AF12: =IFERROR(__xludf.DUMMYFUNCTION("""COMPUTED_VALUE"""),"TLPG TJ PERAK") -> TLPG TJ PERAK | AG12: =IFERROR(__xludf.DUMMYFUNCTION("""COMPUTED_VALUE"""),4.0) -> 4 | AH12: PT RAMA MANGGALA GAS | AJ12: =IFERROR(__xludf.DUMMYFUNCTION("""COMPUTED_VALUE"""),11.0) -> 11 | AK12: =IFERROR(__xludf.DUMMYFUNCTION("""COMPUTED_VALUE"""),"N 9579 US") -> N 9579 US | AL12: =IFERROR(__xludf.DUMMYFUNCTION("""COMPUTED_VALUE"""),"TLPG TJ PERAK") -> TLPG TJ PERAK | AM12: =IFERROR(__xludf.DUMMYFUNCTION("""COMPUTED_VALUE"""),5.0) -> 5 | AN12: PT BINA ANUGERAH INTI KIMIA | AP12: =IFERROR(__xludf.DUMMYFUNCTION("""COMPUTED_VALUE"""),11.0) -> 11 | AQ12: =IFERROR(__xludf.DUMMYFUNCTION("""COMPUTED_VALUE"""),"L 9161 UB") -> L 9161 UB | AR12: =IFERROR(__xludf.DUMMYFUNCTION("""COMPUTED_VALUE"""),"TLPG TJ PERAK") -> TLPG TJ PERAK | AS12: =IFERROR(__xludf.DUMMYFUNCTION("""COMPUTED_VALUE"""),6.0) -> 6 | AT12: PT GEHA INTI CITRA | AV12: ='KENDARAAN P1'!A:A -> B 9880 SFU
A13: =IFERROR(__xludf.DUMMYFUNCTION("""COMPUTED_VALUE"""),"AE 9061 UJ") -> AE 9061 UJ | B13: =IFERROR(__xludf.DUMMYFUNCTION("""COMPUTED_VALUE"""),"TLPG TJ PERAK") -> TLPG TJ PERAK | C13: =IFERROR(__xludf.DUMMYFUNCTION("""COMPUTED_VALUE"""),1.0) -> 1 | D13: 1 | E13: PT NUR WISTARA ABADI | G13: 12 | H13: =IFERROR(__xludf.DUMMYFUNCTION("""COMPUTED_VALUE"""),"B 9711 SFU") -> B 9711 SFU | I13: =IFERROR(__xludf.DUMMYFUNCTION("""COMPUTED_VALUE"""),"TLPG TJ WANGI") -> TLPG TJ WANGI | J13: =IFERROR(__xludf.DUMMYFUNCTION("""COMPUTED_VALUE"""),1.0) -> 1 | L13: =IFERROR(__xludf.DUMMYFUNCTION("""COMPUTED_VALUE"""),12.0) -> 12 | M13: =IFERROR(__xludf.DUMMYFUNCTION("""COMPUTED_VALUE"""),"B 9711 SFU") -> B 9711 SFU | N13: =IFERROR(__xludf.DUMMYFUNCTION("""COMPUTED_VALUE"""),"TLPG TJ WANGI") -> TLPG TJ WANGI | O13: =IFERROR(__xludf.DUMMYFUNCTION("""COMPUTED_VALUE"""),1.0) -> 1 | P13: PT PATRA NIAGA 1 | R13: =IFERROR(__xludf.DUMMYFUNCTION("""COMPUTED_VALUE"""),12.0) -> 12 | S13: =IFERROR(__xludf.DUMMYFUNCTION("""COMPUTED_VALUE"""),"AE 8828 UQ") -> AE 8828 UQ | T13: =IFERROR(__xludf.DUMMYFUNCTION("""COMPUTED_VALUE"""),"TLPG TJ PERAK") -> TLPG TJ PERAK | U13: =IFERROR(__xludf.DUMMYFUNCTION("""COMPUTED_VALUE"""),2.0) -> 2 | V13: PT SEKAWAN GAS NUSA | X13: =IFERROR(__xludf.DUMMYFUNCTION("""COMPUTED_VALUE"""),12.0) -> 12 | Y13: =IFERROR(__xludf.DUMMYFUNCTION("""COMPUTED_VALUE"""),"AG 8225 UG") -> AG 8225 UG | Z13: =IFERROR(__xludf.DUMMYFUNCTION("""COMPUTED_VALUE"""),"TLPG TJ PERAK") -> TLPG TJ PERAK | AA13: =IFERROR(__xludf.DUMMYFUNCTION("""COMPUTED_VALUE"""),3.0) -> 3 | AB13: PT SINAR HASIL BUANA | AD13: =IFERROR(__xludf.DUMMYFUNCTION("""COMPUTED_VALUE"""),12.0) -> 12 | AE13: =IFERROR(__xludf.DUMMYFUNCTION("""COMPUTED_VALUE"""),"AG 8818 UK") -> AG 8818 UK | AF13: =IFERROR(__xludf.DUMMYFUNCTION("""COMPUTED_VALUE"""),"TLPG TJ PERAK") -> TLPG TJ PERAK | AG13: =IFERROR(__xludf.DUMMYFUNCTION("""COMPUTED_VALUE"""),4.0) -> 4 | AH13: PT RAMA MANGGALA GAS | AJ13: =IFERROR(__xludf.DUMMYFUNCTION("""COMPUTED_VALUE"""),12.0) -> 12 | AK13: =IFERROR(__xludf.DUMMYFUNCTION("""COMPUTED_VALUE"""),"AG 9151 UL") -> AG 9151 UL | AL13: =IFERROR(__xludf.DUMMYFUNCTION("""COMPUTED_VALUE"""),"TLPG TJ PERAK") -> TLPG TJ PERAK | AM13: =IFERROR(__xludf.DUMMYFUNCTION("""COMPUTED_VALUE"""),5.0) -> 5 | AN13: PT SUMINAR MITRAGAS SELARAS | AP13: =IFERROR(__xludf.DUMMYFUNCTION("""COMPUTED_VALUE"""),12.0) -> 12 | AQ13: =IFERROR(__xludf.DUMMYFUNCTION("""COMPUTED_VALUE"""),"L 9290 UQ") -> L 9290 UQ | AR13: =IFERROR(__xludf.DUMMYFUNCTION("""COMPUTED_VALUE"""),"TLPG TJ PERAK") -> TLPG TJ PERAK | AS13: =IFERROR(__xludf.DUMMYFUNCTION("""COMPUTED_VALUE"""),6.0) -> 6 | AT13: PT GEHA INTI CITRA | AV13: ='KENDARAAN P1'!A:A -> L 9837 UJ
A14: =IFERROR(__xludf.DUMMYFUNCTION("""COMPUTED_VALUE"""),"AE 8835 UQ") -> AE 8835 UQ | B14: =IFERROR(__xludf.DUMMYFUNCTION("""COMPUTED_VALUE"""),"TLPG TJ PERAK") -> TLPG TJ PERAK | C14: =IFERROR(__xludf.DUMMYFUNCTION("""COMPUTED_VALUE"""),1.0) -> 1 | D14: 2 | E14: PT SEKAWAN GAS NUSA | G14: 13 | H14: =IFERROR(__xludf.DUMMYFUNCTION("""COMPUTED_VALUE"""),"B 9914 PEI") -> B 9914 PEI | I14: =IFERROR(__xludf.DUMMYFUNCTION("""COMPUTED_VALUE"""),"TLPG MANGGIS") -> TLPG MANGGIS | J14: =IFERROR(__xludf.DUMMYFUNCTION("""COMPUTED_VALUE"""),1.0) -> 1 | L14: =IFERROR(__xludf.DUMMYFUNCTION("""COMPUTED_VALUE"""),13.0) -> 13 | M14: =IFERROR(__xludf.DUMMYFUNCTION("""COMPUTED_VALUE"""),"B 9914 PEI") -> B 9914 PEI | N14: =IFERROR(__xludf.DUMMYFUNCTION("""COMPUTED_VALUE"""),"TLPG MANGGIS") -> TLPG MANGGIS | O14: =IFERROR(__xludf.DUMMYFUNCTION("""COMPUTED_VALUE"""),1.0) -> 1 | P14: SPPBE-PT. Pancadarma Puspawira Putra | R14: =IFERROR(__xludf.DUMMYFUNCTION("""COMPUTED_VALUE"""),13.0) -> 13 | S14: =IFERROR(__xludf.DUMMYFUNCTION("""COMPUTED_VALUE"""),"AE 9634 UJ") -> AE 9634 UJ | T14: =IFERROR(__xludf.DUMMYFUNCTION("""COMPUTED_VALUE"""),"TLPG TJ PERAK") -> TLPG TJ PERAK | U14: =IFERROR(__xludf.DUMMYFUNCTION("""COMPUTED_VALUE"""),2.0) -> 2 | V14: PT KARYA USAHA MANDIRI LESTARI | X14: =IFERROR(__xludf.DUMMYFUNCTION("""COMPUTED_VALUE"""),13.0) -> 13 | Y14: =IFERROR(__xludf.DUMMYFUNCTION("""COMPUTED_VALUE"""),"AG 8374 UG") -> AG 8374 UG | Z14: =IFERROR(__xludf.DUMMYFUNCTION("""COMPUTED_VALUE"""),"TLPG TJ PERAK") -> TLPG TJ PERAK | AA14: =IFERROR(__xludf.DUMMYFUNCTION("""COMPUTED_VALUE"""),3.0) -> 3 | AB14: PT PANDU MANUNGGAL KARSA | AD14: =IFERROR(__xludf.DUMMYFUNCTION("""COMPUTED_VALUE"""),13.0) -> 13 | AE14: =IFERROR(__xludf.DUMMYFUNCTION("""COMPUTED_VALUE"""),"L 8013 UX") -> L 8013 UX | AF14: =IFERROR(__xludf.DUMMYFUNCTION("""COMPUTED_VALUE"""),"TLPG MEM GRESIK") -> TLPG MEM GRESIK | AG14: =IFERROR(__xludf.DUMMYFUNCTION("""COMPUTED_VALUE"""),4.0) -> 4 | AH14: PT PERMATA ENERGI BUMI INDONESIA | AJ14: =IFERROR(__xludf.DUMMYFUNCTION("""COMPUTED_VALUE"""),13.0) -> 13 | AK14: =IFERROR(__xludf.DUMMYFUNCTION("""COMPUTED_VALUE"""),"DK 8198 BK") -> DK 8198 BK | AL14: =IFERROR(__xludf.DUMMYFUNCTION("""COMPUTED_VALUE"""),"TLPG MANGGIS") -> TLPG MANGGIS | AM14: =IFERROR(__xludf.DUMMYFUNCTION("""COMPUTED_VALUE"""),5.0) -> 5 | AN14: SPPBE-PT. Sari Dharma Mandiri | AP14: =IFERROR(__xludf.DUMMYFUNCTION("""COMPUTED_VALUE"""),13.0) -> 13 | AQ14: =IFERROR(__xludf.DUMMYFUNCTION("""COMPUTED_VALUE"""),"L 9476 UL") -> L 9476 UL | AR14: =IFERROR(__xludf.DUMMYFUNCTION("""COMPUTED_VALUE"""),"TLPG TJ PERAK") -> TLPG TJ PERAK | AS14: =IFERROR(__xludf.DUMMYFUNCTION("""COMPUTED_VALUE"""),6.0) -> 6 | AT14: PT HELA CITRA AGUNG | AV14: ='KENDARAAN P1'!A:A -> B 9882 SFU
A15: =IFERROR(__xludf.DUMMYFUNCTION("""COMPUTED_VALUE"""),"AG 8093 EI") -> AG 8093 EI | B15: =IFERROR(__xludf.DUMMYFUNCTION("""COMPUTED_VALUE"""),"TLPG MEM GRESIK") -> TLPG MEM GRESIK | C15: =IFERROR(__xludf.DUMMYFUNCTION("""COMPUTED_VALUE"""),1.0) -> 1 | D15: 3 | E15: PT RADIMA JAYA KEDIRI | G15: 14 | H15: =IFERROR(__xludf.DUMMYFUNCTION("""COMPUTED_VALUE"""),"DK 8011 UK") -> DK 8011 UK | I15: =IFERROR(__xludf.DUMMYFUNCTION("""COMPUTED_VALUE"""),"TLPG MANGGIS") -> TLPG MANGGIS | J15: =IFERROR(__xludf.DUMMYFUNCTION("""COMPUTED_VALUE"""),1.0) -> 1 | L15: =IFERROR(__xludf.DUMMYFUNCTION("""COMPUTED_VALUE"""),14.0) -> 14 | M15: =IFERROR(__xludf.DUMMYFUNCTION("""COMPUTED_VALUE"""),"DK 8011 UK") -> DK 8011 UK | N15: =IFERROR(__xludf.DUMMYFUNCTION("""COMPUTED_VALUE"""),"TLPG MANGGIS") -> TLPG MANGGIS | O15: =IFERROR(__xludf.DUMMYFUNCTION("""COMPUTED_VALUE"""),1.0) -> 1 | P15: SPPBE-PT. Ayu Sari Pertiwi | R15: =IFERROR(__xludf.DUMMYFUNCTION("""COMPUTED_VALUE"""),14.0) -> 14 | S15: =IFERROR(__xludf.DUMMYFUNCTION("""COMPUTED_VALUE"""),"AG 8032 YQ") -> AG 8032 YQ | T15: =IFERROR(__xludf.DUMMYFUNCTION("""COMPUTED_VALUE"""),"TLPG TJ PERAK") -> TLPG TJ PERAK | U15: =IFERROR(__xludf.DUMMYFUNCTION("""COMPUTED_VALUE"""),2.0) -> 2 | V15: PT BINTANG CIPTA PERSADA | X15: =IFERROR(__xludf.DUMMYFUNCTION("""COMPUTED_VALUE"""),14.0) -> 14 | Y15: =IFERROR(__xludf.DUMMYFUNCTION("""COMPUTED_VALUE"""),"AG 8380 KL") -> AG 8380 KL | Z15: =IFERROR(__xludf.DUMMYFUNCTION("""COMPUTED_VALUE"""),"TLPG TJ PERAK") -> TLPG TJ PERAK | AA15: =IFERROR(__xludf.DUMMYFUNCTION("""COMPUTED_VALUE"""),3.0) -> 3 | AB15: PT AGUNG CATUR UTAMA GROUP | AD15: =IFERROR(__xludf.DUMMYFUNCTION("""COMPUTED_VALUE"""),14.0) -> 14 | AE15: =IFERROR(__xludf.DUMMYFUNCTION("""COMPUTED_VALUE"""),"L 8440 UD") -> L 8440 UD | AF15: =IFERROR(__xludf.DUMMYFUNCTION("""COMPUTED_VALUE"""),"TLPG MEM GRESIK") -> TLPG MEM GRESIK | AG15: =IFERROR(__xludf.DUMMYFUNCTION("""COMPUTED_VALUE"""),4.0) -> 4 | AH15: PT BINA MAKMUR SENTOSA LESTARI | AJ15: =IFERROR(__xludf.DUMMYFUNCTION("""COMPUTED_VALUE"""),14.0) -> 14 | AK15: =IFERROR(__xludf.DUMMYFUNCTION("""COMPUTED_VALUE"""),"DK 8203 KO") -> DK 8203 KO | AL15: =IFERROR(__xludf.DUMMYFUNCTION("""COMPUTED_VALUE"""),"TLPG MANGGIS") -> TLPG MANGGIS | AM15: =IFERROR(__xludf.DUMMYFUNCTION("""COMPUTED_VALUE"""),5.0) -> 5 | AN15: SPPBE-PT. Dasico Panca Rena | AP15: =IFERROR(__xludf.DUMMYFUNCTION("""COMPUTED_VALUE"""),14.0) -> 14 | AQ15: =IFERROR(__xludf.DUMMYFUNCTION("""COMPUTED_VALUE"""),"L 9489 UL") -> L 9489 UL | AR15: =IFERROR(__xludf.DUMMYFUNCTION("""COMPUTED_VALUE"""),"TLPG TJ PERAK") -> TLPG TJ PERAK | AS15: =IFERROR(__xludf.DUMMYFUNCTION("""COMPUTED_VALUE"""),6.0) -> 6 | AT15: PT HELA CITRA AGUNG | AV15: ='KENDARAAN P1'!A:A -> B 9883 SFU
A16: =IFERROR(__xludf.DUMMYFUNCTION("""COMPUTED_VALUE"""),"AG 9876 RK") -> AG 9876 RK | B16: =IFERROR(__xludf.DUMMYFUNCTION("""COMPUTED_VALUE"""),"TLPG MEM GRESIK") -> TLPG MEM GRESIK | C16: =IFERROR(__xludf.DUMMYFUNCTION("""COMPUTED_VALUE"""),1.0) -> 1 | D16: 2 | E16: PT BINTANG CIPTA PERSADA | G16: 15 | H16: =IFERROR(__xludf.DUMMYFUNCTION("""COMPUTED_VALUE"""),"DK 8018 UF") -> DK 8018 UF | I16: =IFERROR(__xludf.DUMMYFUNCTION("""COMPUTED_VALUE"""),"TLPG MANGGIS") -> TLPG MANGGIS | J16: =IFERROR(__xludf.DUMMYFUNCTION("""COMPUTED_VALUE"""),1.0) -> 1 | L16: =IFERROR(__xludf.DUMMYFUNCTION("""COMPUTED_VALUE"""),15.0) -> 15 | M16: =IFERROR(__xludf.DUMMYFUNCTION("""COMPUTED_VALUE"""),"DK 8018 UF") -> DK 8018 UF | N16: =IFERROR(__xludf.DUMMYFUNCTION("""COMPUTED_VALUE"""),"TLPG MANGGIS") -> TLPG MANGGIS | O16: =IFERROR(__xludf.DUMMYFUNCTION("""COMPUTED_VALUE"""),1.0) -> 1 | P16: SPPBE-PT. Gaya Investama | R16: =IFERROR(__xludf.DUMMYFUNCTION("""COMPUTED_VALUE"""),15.0) -> 15 | S16: =IFERROR(__xludf.DUMMYFUNCTION("""COMPUTED_VALUE"""),"AG 8070 UW") -> AG 8070 UW | T16: =IFERROR(__xludf.DUMMYFUNCTION("""COMPUTED_VALUE"""),"TLPG TJ PERAK") -> TLPG TJ PERAK | U16: =IFERROR(__xludf.DUMMYFUNCTION("""COMPUTED_VALUE"""),2.0) -> 2 | V16: PT LAJU | X16: =IFERROR(__xludf.DUMMYFUNCTION("""COMPUTED_VALUE"""),15.0) -> 15 | Y16: =IFERROR(__xludf.DUMMYFUNCTION("""COMPUTED_VALUE"""),"AG 8384 UE") -> AG 8384 UE | Z16: =IFERROR(__xludf.DUMMYFUNCTION("""COMPUTED_VALUE"""),"TLPG TJ PERAK") -> TLPG TJ PERAK | AA16: =IFERROR(__xludf.DUMMYFUNCTION("""COMPUTED_VALUE"""),3.0) -> 3 | AB16: PT SURYA ADHILESTARI | AD16: =IFERROR(__xludf.DUMMYFUNCTION("""COMPUTED_VALUE"""),15.0) -> 15 | AE16: =IFERROR(__xludf.DUMMYFUNCTION("""COMPUTED_VALUE"""),"L 8537 UD") -> L 8537 UD | AF16: =IFERROR(__xludf.DUMMYFUNCTION("""COMPUTED_VALUE"""),"TLPG TJ PERAK") -> TLPG TJ PERAK | AG16: =IFERROR(__xludf.DUMMYFUNCTION("""COMPUTED_VALUE"""),4.0) -> 4 | AH16: PT GOENADI GASINDO PRATAMA | AJ16: =IFERROR(__xludf.DUMMYFUNCTION("""COMPUTED_VALUE"""),15.0) -> 15 | AK16: =IFERROR(__xludf.DUMMYFUNCTION("""COMPUTED_VALUE"""),"DK 8204 KO") -> DK 8204 KO | AL16: =IFERROR(__xludf.DUMMYFUNCTION("""COMPUTED_VALUE"""),"TLPG MANGGIS") -> TLPG MANGGIS | AM16: =IFERROR(__xludf.DUMMYFUNCTION("""COMPUTED_VALUE"""),5.0) -> 5 | AN16: SPPBE-PT. Dasico Panca Rena | AP16: =IFERROR(__xludf.DUMMYFUNCTION("""COMPUTED_VALUE"""),15.0) -> 15 | AQ16: =IFERROR(__xludf.DUMMYFUNCTION("""COMPUTED_VALUE"""),"L 9507 UL") -> L 9507 UL | AR16: =IFERROR(__xludf.DUMMYFUNCTION("""COMPUTED_VALUE"""),"TLPG TJ PERAK") -> TLPG TJ PERAK | AS16: =IFERROR(__xludf.DUMMYFUNCTION("""COMPUTED_VALUE"""),6.0) -> 6 | AT16: PT HELA CITRA AGUNG | AV16: ='KENDARAAN P1'!A:A -> B 9088 SEI
A17: =IFERROR(__xludf.DUMMYFUNCTION("""COMPUTED_VALUE"""),"B 9080 SEI") -> B 9080 SEI | B17: =IFERROR(__xludf.DUMMYFUNCTION("""COMPUTED_VALUE"""),"TLPG TJ WANGI") -> TLPG TJ WANGI | C17: =IFERROR(__xludf.DUMMYFUNCTION("""COMPUTED_VALUE"""),1.0) -> 1 | D17: 1 | E17: PT PATRA NIAGA 1 | G17: 16 | H17: =IFERROR(__xludf.DUMMYFUNCTION("""COMPUTED_VALUE"""),"DK 8696 AS") -> DK 8696 AS | I17: =IFERROR(__xludf.DUMMYFUNCTION("""COMPUTED_VALUE"""),"TLPG MANGGIS") -> TLPG MANGGIS | J17: =IFERROR(__xludf.DUMMYFUNCTION("""COMPUTED_VALUE"""),1.0) -> 1 | L17: =IFERROR(__xludf.DUMMYFUNCTION("""COMPUTED_VALUE"""),16.0) -> 16 | M17: =IFERROR(__xludf.DUMMYFUNCTION("""COMPUTED_VALUE"""),"DK 8696 AS") -> DK 8696 AS | N17: =IFERROR(__xludf.DUMMYFUNCTION("""COMPUTED_VALUE"""),"TLPG MANGGIS") -> TLPG MANGGIS | O17: =IFERROR(__xludf.DUMMYFUNCTION("""COMPUTED_VALUE"""),1.0) -> 1 | P17: Data Company Belum Ada | R17: =IFERROR(__xludf.DUMMYFUNCTION("""COMPUTED_VALUE"""),16.0) -> 16 | S17: =IFERROR(__xludf.DUMMYFUNCTION("""COMPUTED_VALUE"""),"AG 9312 UW") -> AG 9312 UW | T17: =IFERROR(__xludf.DUMMYFUNCTION("""COMPUTED_VALUE"""),"TLPG TJ PERAK") -> TLPG TJ PERAK | U17: =IFERROR(__xludf.DUMMYFUNCTION("""COMPUTED_VALUE"""),2.0) -> 2 | V17: PT LAJU | X17: =IFERROR(__xludf.DUMMYFUNCTION("""COMPUTED_VALUE"""),16.0) -> 16 | Y17: =IFERROR(__xludf.DUMMYFUNCTION("""COMPUTED_VALUE"""),"B 9115 SEI") -> B 9115 SEI | Z17: =IFERROR(__xludf.DUMMYFUNCTION("""COMPUTED_VALUE"""),"TLPG MEM GRESIK") -> TLPG MEM GRESIK | AA17: =IFERROR(__xludf.DUMMYFUNCTION("""COMPUTED_VALUE"""),3.0) -> 3 | AB17: PT PATRA NIAGA | AD17: =IFERROR(__xludf.DUMMYFUNCTION("""COMPUTED_VALUE"""),16.0) -> 16 | AE17: =IFERROR(__xludf.DUMMYFUNCTION("""COMPUTED_VALUE"""),"AE 8527 UJ") -> AE 8527 UJ | AF17: =IFERROR(__xludf.DUMMYFUNCTION("""COMPUTED_VALUE"""),"TLPG TJ PERAK") -> TLPG TJ PERAK | AG17: =IFERROR(__xludf.DUMMYFUNCTION("""COMPUTED_VALUE"""),4.0) -> 4 | AH17: PT RAMA MANGGALA GAS | AJ17: =IFERROR(__xludf.DUMMYFUNCTION("""COMPUTED_VALUE"""),16.0) -> 16 | AK17: =IFERROR(__xludf.DUMMYFUNCTION("""COMPUTED_VALUE"""),"DK 8859 CK") -> DK 8859 CK | AL17: =IFERROR(__xludf.DUMMYFUNCTION("""COMPUTED_VALUE"""),"TLPG MANGGIS") -> TLPG MANGGIS | AM17: =IFERROR(__xludf.DUMMYFUNCTION("""COMPUTED_VALUE"""),5.0) -> 5 | AN17: SPPBE-PT. Pande Agung Dewata | AP17: =IFERROR(__xludf.DUMMYFUNCTION("""COMPUTED_VALUE"""),16.0) -> 16 | AQ17: =IFERROR(__xludf.DUMMYFUNCTION("""COMPUTED_VALUE"""),"L 9644 BB") -> L 9644 BB | AR17: =IFERROR(__xludf.DUMMYFUNCTION("""COMPUTED_VALUE"""),"TLPG TJ PERAK") -> TLPG TJ PERAK | AS17: =IFERROR(__xludf.DUMMYFUNCTION("""COMPUTED_VALUE"""),6.0) -> 6 | AT17: PT ANDHIKA PUTRA TRIGAS LENTERA | AV17: ='KENDARAAN P1'!A:A -> L 8079 UQ
A18: =IFERROR(__xludf.DUMMYFUNCTION("""COMPUTED_VALUE"""),"B 9089 SEI") -> B 9089 SEI | B18: =IFERROR(__xludf.DUMMYFUNCTION("""COMPUTED_VALUE"""),"TLPG MEM GRESIK") -> TLPG MEM GRESIK | C18: =IFERROR(__xludf.DUMMYFUNCTION("""COMPUTED_VALUE"""),1.0) -> 1 | D18: 1 | E18: PT PATRA NIAGA | G18: 17 | H18: =IFERROR(__xludf.DUMMYFUNCTION("""COMPUTED_VALUE"""),"DR 8761 DC") -> DR 8761 DC | I18: =IFERROR(__xludf.DUMMYFUNCTION("""COMPUTED_VALUE"""),"TLPG LOMBOK") -> TLPG LOMBOK | J18: =IFERROR(__xludf.DUMMYFUNCTION("""COMPUTED_VALUE"""),1.0) -> 1 | L18: =IFERROR(__xludf.DUMMYFUNCTION("""COMPUTED_VALUE"""),17.0) -> 17 | M18: =IFERROR(__xludf.DUMMYFUNCTION("""COMPUTED_VALUE"""),"DR 8761 DC") -> DR 8761 DC | N18: =IFERROR(__xludf.DUMMYFUNCTION("""COMPUTED_VALUE"""),"TLPG LOMBOK") -> TLPG LOMBOK | O18: =IFERROR(__xludf.DUMMYFUNCTION("""COMPUTED_VALUE"""),1.0) -> 1 | P18: SPPBE-PT. Om Agus | R18: =IFERROR(__xludf.DUMMYFUNCTION("""COMPUTED_VALUE"""),17.0) -> 17 | S18: =IFERROR(__xludf.DUMMYFUNCTION("""COMPUTED_VALUE"""),"B 9098 SEI") -> B 9098 SEI | T18: =IFERROR(__xludf.DUMMYFUNCTION("""COMPUTED_VALUE"""),"TLPG MEM GRESIK") -> TLPG MEM GRESIK | U18: =IFERROR(__xludf.DUMMYFUNCTION("""COMPUTED_VALUE"""),2.0) -> 2 | V18: PT PATRA NIAGA | X18: =IFERROR(__xludf.DUMMYFUNCTION("""COMPUTED_VALUE"""),17.0) -> 17 | Y18: =IFERROR(__xludf.DUMMYFUNCTION("""COMPUTED_VALUE"""),"B 9203 TEK") -> B 9203 TEK | Z18: =IFERROR(__xludf.DUMMYFUNCTION("""COMPUTED_VALUE"""),"TLPG MEM GRESIK") -> TLPG MEM GRESIK | AA18: =IFERROR(__xludf.DUMMYFUNCTION("""COMPUTED_VALUE"""),3.0) -> 3 | AB18: PT ADAM TRANS | AD18: =IFERROR(__xludf.DUMMYFUNCTION("""COMPUTED_VALUE"""),17.0) -> 17 | AE18: =IFERROR(__xludf.DUMMYFUNCTION("""COMPUTED_VALUE"""),"AE 8858 UT") -> AE 8858 UT | AF18: =IFERROR(__xludf.DUMMYFUNCTION("""COMPUTED_VALUE"""),"TLPG TJ PERAK") -> TLPG TJ PERAK | AG18: =IFERROR(__xludf.DUMMYFUNCTION("""COMPUTED_VALUE"""),4.0) -> 4 | AH18: PT GANGSAR SENTOSA PETROLIUM | AJ18: =IFERROR(__xludf.DUMMYFUNCTION("""COMPUTED_VALUE"""),17.0) -> 17 | AK18: =IFERROR(__xludf.DUMMYFUNCTION("""COMPUTED_VALUE"""),"DR 8129 AH") -> DR 8129 AH | AL18: =IFERROR(__xludf.DUMMYFUNCTION("""COMPUTED_VALUE"""),"TLPG LOMBOK") -> TLPG LOMBOK | AM18: =IFERROR(__xludf.DUMMYFUNCTION("""COMPUTED_VALUE"""),5.0) -> 5 | AN18: SPPBE-PT. Surya Adiguna Indogas | AP18: =IFERROR(__xludf.DUMMYFUNCTION("""COMPUTED_VALUE"""),17.0) -> 17 | AQ18: =IFERROR(__xludf.DUMMYFUNCTION("""COMPUTED_VALUE"""),"L 9822 UE") -> L 9822 UE | AR18: =IFERROR(__xludf.DUMMYFUNCTION("""COMPUTED_VALUE"""),"TLPG TJ PERAK") -> TLPG TJ PERAK | AS18: =IFERROR(__xludf.DUMMYFUNCTION("""COMPUTED_VALUE"""),6.0) -> 6 | AT18: PT DHARMA TECH INFOMEDIA | AV18: ='KENDARAAN P1'!A:A -> L 8088 UR
A19: =IFERROR(__xludf.DUMMYFUNCTION("""COMPUTED_VALUE"""),"B 9711 SFU") -> B 9711 SFU | B19: =IFERROR(__xludf.DUMMYFUNCTION("""COMPUTED_VALUE"""),"TLPG TJ WANGI") -> TLPG TJ WANGI | C19: =IFERROR(__xludf.DUMMYFUNCTION("""COMPUTED_VALUE"""),1.0) -> 1 | D19: 1 | E19: PT PATRA NIAGA 1 | G19: 18 | H19: =IFERROR(__xludf.DUMMYFUNCTION("""COMPUTED_VALUE"""),"L 8116 UUC") -> L 8116 UUC | I19: =IFERROR(__xludf.DUMMYFUNCTION("""COMPUTED_VALUE"""),"TLPG BIMA") -> TLPG BIMA | J19: =IFERROR(__xludf.DUMMYFUNCTION("""COMPUTED_VALUE"""),1.0) -> 1 | L19: =IFERROR(__xludf.DUMMYFUNCTION("""COMPUTED_VALUE"""),18.0) -> 18 | M19: =IFERROR(__xludf.DUMMYFUNCTION("""COMPUTED_VALUE"""),"L 8116 UUC") -> L 8116 UUC | N19: =IFERROR(__xludf.DUMMYFUNCTION("""COMPUTED_VALUE"""),"TLPG BIMA") -> TLPG BIMA | O19: =IFERROR(__xludf.DUMMYFUNCTION("""COMPUTED_VALUE"""),1.0) -> 1 | P19: PT. SUMBAWA DUTA ENERGY | R19: =IFERROR(__xludf.DUMMYFUNCTION("""COMPUTED_VALUE"""),18.0) -> 18 | S19: =IFERROR(__xludf.DUMMYFUNCTION("""COMPUTED_VALUE"""),"B 9099 SEI") -> B 9099 SEI | T19: =IFERROR(__xludf.DUMMYFUNCTION("""COMPUTED_VALUE"""),"TLPG MEM GRESIK") -> TLPG MEM GRESIK | U19: =IFERROR(__xludf.DUMMYFUNCTION("""COMPUTED_VALUE"""),2.0) -> 2 | V19: PT PATRA NIAGA | X19: =IFERROR(__xludf.DUMMYFUNCTION("""COMPUTED_VALUE"""),18.0) -> 18 | Y19: =IFERROR(__xludf.DUMMYFUNCTION("""COMPUTED_VALUE"""),"B 9712 SFU") -> B 9712 SFU | Z19: =IFERROR(__xludf.DUMMYFUNCTION("""COMPUTED_VALUE"""),"TLPG MEM GRESIK") -> TLPG MEM GRESIK | AA19: =IFERROR(__xludf.DUMMYFUNCTION("""COMPUTED_VALUE"""),3.0) -> 3 | AB19: PT PATRA NIAGA | AD19: =IFERROR(__xludf.DUMMYFUNCTION("""COMPUTED_VALUE"""),18.0) -> 18 | AE19: =IFERROR(__xludf.DUMMYFUNCTION("""COMPUTED_VALUE"""),"AG 8115 UC") -> AG 8115 UC | AF19: =IFERROR(__xludf.DUMMYFUNCTION("""COMPUTED_VALUE"""),"TLPG TJ PERAK") -> TLPG TJ PERAK | AG19: =IFERROR(__xludf.DUMMYFUNCTION("""COMPUTED_VALUE"""),4.0) -> 4 | AH19: PT SURYA ADI LESTARI | AJ19: =IFERROR(__xludf.DUMMYFUNCTION("""COMPUTED_VALUE"""),18.0) -> 18 | AK19: =IFERROR(__xludf.DUMMYFUNCTION("""COMPUTED_VALUE"""),"DR 8309 LH") -> DR 8309 LH | AL19: =IFERROR(__xludf.DUMMYFUNCTION("""COMPUTED_VALUE"""),"TLPG LOMBOK") -> TLPG LOMBOK | AM19: =IFERROR(__xludf.DUMMYFUNCTION("""COMPUTED_VALUE"""),5.0) -> 5 | AN19: SPPBE-PT. Bintang Energi Abadi | AP19: =IFERROR(__xludf.DUMMYFUNCTION("""COMPUTED_VALUE"""),18.0) -> 18 | AQ19: =IFERROR(__xludf.DUMMYFUNCTION("""COMPUTED_VALUE"""),"P 8018 UF") -> P 8018 UF | AR19: =IFERROR(__xludf.DUMMYFUNCTION("""COMPUTED_VALUE"""),"TLPG TJ WANGI") -> TLPG TJ WANGI | AS19: =IFERROR(__xludf.DUMMYFUNCTION("""COMPUTED_VALUE"""),6.0) -> 6 | AT19: Data Company Belum Ada | AV19: ='KENDARAAN P1'!A:A -> B 9881 SFU
A20: =IFERROR(__xludf.DUMMYFUNCTION("""COMPUTED_VALUE"""),"B 9914 PEI") -> B 9914 PEI | B20: =IFERROR(__xludf.DUMMYFUNCTION("""COMPUTED_VALUE"""),"TLPG MANGGIS") -> TLPG MANGGIS | C20: =IFERROR(__xludf.DUMMYFUNCTION("""COMPUTED_VALUE"""),1.0) -> 1 | D20: 1 | E20: SPPBE-PT. Pancadarma Puspawira Putra | G20: 19 | H20: =IFERROR(__xludf.DUMMYFUNCTION("""COMPUTED_VALUE"""),"N 8435 UZ") -> N 8435 UZ | I20: =IFERROR(__xludf.DUMMYFUNCTION("""COMPUTED_VALUE"""),"TLPG MEM GRESIK") -> TLPG MEM GRESIK | J20: =IFERROR(__xludf.DUMMYFUNCTION("""COMPUTED_VALUE"""),1.0) -> 1 | L20: =IFERROR(__xludf.DUMMYFUNCTION("""COMPUTED_VALUE"""),19.0) -> 19 | M20: =IFERROR(__xludf.DUMMYFUNCTION("""COMPUTED_VALUE"""),"N 8435 UZ") -> N 8435 UZ | N20: =IFERROR(__xludf.DUMMYFUNCTION("""COMPUTED_VALUE"""),"TLPG MEM GRESIK") -> TLPG MEM GRESIK | O20: =IFERROR(__xludf.DUMMYFUNCTION("""COMPUTED_VALUE"""),1.0) -> 1 | P20: PT SENTOSA GASINDO RAYA | R20: =IFERROR(__xludf.DUMMYFUNCTION("""COMPUTED_VALUE"""),19.0) -> 19 | S20: =IFERROR(__xludf.DUMMYFUNCTION("""COMPUTED_VALUE"""),"N 8857 UR") -> N 8857 UR | T20: =IFERROR(__xludf.DUMMYFUNCTION("""COMPUTED_VALUE"""),"TLPG MEM GRESIK") -> TLPG MEM GRESIK | U20: =IFERROR(__xludf.DUMMYFUNCTION("""COMPUTED_VALUE"""),2.0) -> 2 | V20: PT PATRA NIAGA | X20: =IFERROR(__xludf.DUMMYFUNCTION("""COMPUTED_VALUE"""),19.0) -> 19 | Y20: =IFERROR(__xludf.DUMMYFUNCTION("""COMPUTED_VALUE"""),"B 9880 SFU") -> B 9880 SFU | Z20: =IFERROR(__xludf.DUMMYFUNCTION("""COMPUTED_VALUE"""),"TLPG MEM GRESIK") -> TLPG MEM GRESIK | AA20: =IFERROR(__xludf.DUMMYFUNCTION("""COMPUTED_VALUE"""),3.0) -> 3 | AB20: PT PATRA NIAGA | AD20: =IFERROR(__xludf.DUMMYFUNCTION("""COMPUTED_VALUE"""),19.0) -> 19 | AE20: =IFERROR(__xludf.DUMMYFUNCTION("""COMPUTED_VALUE"""),"AG 8893 YK") -> AG 8893 YK | AF20: =IFERROR(__xludf.DUMMYFUNCTION("""COMPUTED_VALUE"""),"TLPG TJ PERAK") -> TLPG TJ PERAK | AG20: =IFERROR(__xludf.DUMMYFUNCTION("""COMPUTED_VALUE"""),4.0) -> 4 | AH20: PT BINTANG CIPTA PERSADA | AJ20: =IFERROR(__xludf.DUMMYFUNCTION("""COMPUTED_VALUE"""),19.0) -> 19 | AK20: =IFERROR(__xludf.DUMMYFUNCTION("""COMPUTED_VALUE"""),"L 8035 BL") -> L 8035 BL | AL20: =IFERROR(__xludf.DUMMYFUNCTION("""COMPUTED_VALUE"""),"TLPG TJ PERAK") -> TLPG TJ PERAK | AM20: =IFERROR(__xludf.DUMMYFUNCTION("""COMPUTED_VALUE"""),5.0) -> 5 | AN20: PT CAHAYA ANUGERAH GASINDO | AP20: =IFERROR(__xludf.DUMMYFUNCTION("""COMPUTED_VALUE"""),19.0) -> 19 | AQ20: =IFERROR(__xludf.DUMMYFUNCTION("""COMPUTED_VALUE"""),"P 8046 Uf") -> P 8046 Uf | AR20: =IFERROR(__xludf.DUMMYFUNCTION("""COMPUTED_VALUE"""),"TLPG TJ WANGI") -> TLPG TJ WANGI | AS20: =IFERROR(__xludf.DUMMYFUNCTION("""COMPUTED_VALUE"""),6.0) -> 6 | AT20: Data Company Belum Ada | AV20: ='KENDARAAN P1'!A:A -> B 9717 SFU
